Workbook

Sheet Dashboard
B2: =VaR!AU1 -> n=60 | F2: =VaR!AY1 -> % | H2: =VaR!BA1 -> Base Unit | J2: =VaR!BC1 -> $/MT
B3: =VaR!AU2 -> Unit | C3: =VaR!AV2 -> Commodity | D3: =VaR!AW2 -> Mean | E3: =VaR!AX2 -> σ | F3: =VaR!AY2 -> Z_95 | G3: =VaR!AZ2 -> Z_99 | H3: =VaR!BA2 -> Z_95 | I3: =VaR!BB2 -> Z_99 | ... K3: =VaR!BD2 -> Z_99
B4: =VaR!AU3 -> c/bu | C4: =VaR!AV3 -> Wheat | D4: =VaR!AW3 -> -0.0016325426 | E4: =VaR!AX3 -> 0.018083156 | F4: =VaR!AY3 -> 0.029744145 | G4: =VaR!AZ3 -> 0.042067712 | H4: =VaR!BA3 -> 20.966415 | I4: =VaR!BB3 -> 29.653201 | ... K4: =VaR!BD3 -> 10.894586
B5: =VaR!AU4 -> c/bu | C5: =VaR!AV4 -> Kansas Wheat | D5: =VaR!AW4 -> -0.0018955796 | E5: =VaR!AX4 -> 0.016569398 | F5: =VaR!AY4 -> 0.027254235 | G5: =VaR!AZ4 -> 0.038546185 | H5: =VaR!BA4 -> 20.831967 | I5: =VaR!BB4 -> 29.463048 | ... K5: =VaR!BD4 -> 10.824724
B6: =VaR!AU5 -> $/bu | C6: =VaR!AV5 -> Minneapolis Wheat | D6: =VaR!AW5 -> -0.0018797939 | E6: =VaR!AX5 -> 0.013756671 | F6: =VaR!AY5 -> 0.02262771 | G6: =VaR!AZ5 -> 0.032002802 | H6: =VaR!BA5 -> 0.16523753 | I6: =VaR!BB5 -> 0.2336986 | ... K6: =VaR!BD5 -> 8.5860865
B7: =VaR!AU6 -> c/bu | C7: =VaR!AV6 -> Corn | D7: =VaR!AW6 -> -0.00015340277 | E7: =VaR!AX6 -> 0.014975787 | F7: =VaR!AY6 -> 0.024632978 | G7: =VaR!AZ6 -> 0.034838891 | H7: =VaR!BA6 -> 12.269659 | I7: =VaR!BB6 -> 17.353213 | ... K7: =VaR!BD6 -> 6.8302245
B8: =VaR!AU7 -> c/bu | C8: =VaR!AV7 -> Soy | D8: =VaR!AW7 -> 0.0002763678 | E8: =VaR!AX7 -> 0.011235609 | F8: =VaR!AY7 -> 0.018480932 | G8: =VaR!AZ7 -> 0.026137935 | H8: =VaR!BA7 -> 23.41738 | I8: =VaR!BB7 -> 33.119647 | ... K8: =VaR!BD7 -> 12.168158
B9: =VaR!AU8 -> $/st | C9: =VaR!AV8 -> SBM | D9: =VaR!AW8 -> 0.0015280748 | E9: =VaR!AX8 -> 0.014742805 | F9: =VaR!AY8 -> 0.024249756 | G9: =VaR!AZ8 -> 0.034296892 | H9: =VaR!BA8 -> 8.4956408 | I9: =VaR!BB8 -> 12.015547 | ... K9: =VaR!BD8 -> 13.244737
B10: =VaR!AU9 -> c/lb | C10: =VaR!AV9 -> SBO | D10: =VaR!AW9 -> -0.0015858826 | E10: =VaR!AX9 -> 0.014886736 | F10: =VaR!AY9 -> 0.024486501 | G10: =VaR!AZ9 -> 0.034631726 | H10: =VaR!BA9 -> 1.7092733 | I10: =VaR!BB9 -> 2.4174578 | ... K10: =VaR!BD9 -> 53.280771
B11: =VaR!AU10 -> myr/MT | C11: =VaR!AV10 -> CPO | D11: =VaR!AW10 -> 0.00028148589 | E11: =VaR!AX10 -> 0.0099225393 | F11: =VaR!AY10 -> 0.016321125 | G11: =VaR!AZ10 -> 0.023083278 | H11: =VaR!BA10 -> 77.897244 | I11: =VaR!BB10 -> 110.17156 | ... K11: =VaR!BD10 -> 26.547364
B12: =VaR!AU11 -> cny/MT | C12: =VaR!AV11 -> DCE Palm | D12: =VaR!AW11 -> -8.0373658e-06 | E12: =VaR!AX11 -> 0.0080864081 | F12: =VaR!AY11 -> 0.013300958 | G12: =VaR!AZ11 -> 0.018811798 | H12: =VaR!BA11 -> 131.39846 | I12: =VaR!BB11 -> 185.83935 | ... K12: =VaR!BD11 -> 26.101032
B13: =VaR!AU12 -> cny/MT | C13: =VaR!AV12 -> DCE Meal | D13: =VaR!AW12 -> 0.00095749763 | E13: =VaR!AX12 -> 0.0075171136 | F13: =VaR!AY12 -> 0.012364552 | G13: =VaR!AZ12 -> 0.017487421 | H13: =VaR!BA12 -> 40.847205 | I13: =VaR!BB12 -> 57.770981 | ... K13: =VaR!BD12 -> 8.1139018
B14: =VaR!AU13 -> cny/MT | C14: =VaR!AV13 -> DCE BO | D14: =VaR!AW13 -> 0.00061414362 | E14: =VaR!AX13 -> 0.0062962084 | F14: =VaR!AY13 -> 0.010356341 | G14: =VaR!AZ13 -> 0.014647171 | H14: =VaR!BA13 -> 91.621523 | I14: =VaR!BB13 -> 129.58207 | ... K14: =VaR!BD13 -> 18.199729
... B19: =VaR!AU18 -> $/gal | C19: =VaR!AV18 -> Ethanol | D19: =VaR!AW18 -> 0.0018240936 | E19: =VaR!AX18 -> 0.011249487 | F19: =VaR!AY18 -> 0.018503759 | G19: =VaR!AZ18 -> 0.02617022 | H19: =VaR!BA18 -> 0.03809896 | I19: =VaR!BB18 -> 0.053884086 | ... K19: =VaR!BD18 -> 18.040392
B20: =VaR!AU19 -> $/gal | C20: =VaR!AV19 -> Heating Oil | D20: =VaR!AW19 -> 0.0046007422 | E20: =VaR!AX19 -> 0.024186073 | F20: =VaR!AY19 -> 0.03978255 | G20: =VaR!AZ19 -> 0.05626522 | H20: =VaR!BA19 -> 0.1641162 | I20: =VaR!BB19 -> 0.23211267 | ... K20: =VaR!BD19 -> 72.16383 | R20: `
B21: =VaR!AU20 -> $/MT | C21: =VaR!AV20 -> ICE GO | D21: =VaR!AW20 -> 0.0055420811 | E21: =VaR!AX20 -> 0.02663124 | F21: =VaR!AY20 -> 0.043804492 | G21: =VaR!AZ20 -> 0.061953528 | H21: =VaR!BA20 -> 53.286937 | I21: =VaR!BB20 -> 75.364732 | ... K21: =VaR!BD20 -> 75.364732
B22: =VaR!AU21 -> $/bl | C22: =VaR!AV21 -> Light Crude | D22: =VaR!AW21 -> 0.003761533 | E22: =VaR!AX21 -> 0.022116392 | F22: =VaR!AY21 -> 0.036378228 | G22: =VaR!AZ21 -> 0.051450422 | H22: =VaR!BA21 -> 3.0421332 | I22: =VaR!BB21 -> 4.302547 | ... K22: =VaR!BD21 -> 32.183052
B23: =VaR!AU22 -> $/bl | C23: =VaR!AV22 -> Brent Crude | D23: =VaR!AW22 -> 0.004287495 | E23: =VaR!AX22 -> 0.021319156 | F23: =VaR!AY22 -> 0.035066891 | G23: =VaR!AZ22 -> 0.049595774 | H23: =VaR!BA22 -> 3.0826224 | I23: =VaR!BB22 -> 4.3598117 | ... K23: =VaR!BD22 -> 32.611391
B24: =VaR!AU23 -> $/bl | C24: =VaR!AV23 -> RBOB | D24: =VaR!AW23 -> 0.0028360479 | E24: =VaR!AX23 -> 0.020465027 | F24: =VaR!AY23 -> 0.033661974 | G24: =VaR!AZ23 -> 0.047608773 | H24: =VaR!BA23 -> 0.094097821 | I24: =VaR!BB23 -> 0.13308434 | ... K24: =VaR!BD23 -> 46.57952

Sheet Instrument
B1: =_xlfn.XLOOKUP(MAX(C3:C101), C3:C101, B3:B101) -> /WZ26 | E1: =_xlfn.XLOOKUP(MAX(F3:F101), F3:F101, E3:E101) -> /KWZ26 | H1: =_xlfn.XLOOKUP(MAX(I3:I101), I3:I101, H3:H101) -> /MWEZ26 | K1: =_xlfn.XLOOKUP(MAX(L3:L101), L3:L101, K3:K101) -> /CZ26 | N1: =_xlfn.XLOOKUP(MAX(O3:O101), O3:O101, N3:N101) -> /SF27 | Q1: =_xlfn.XLOOKUP(MAX(R3:R101), R3:R101, Q3:Q101) -> /SMZ26 | T1: =_xlfn.XLOOKUP(MAX(U3:U101), U3:U101, T3:T101) -> /BOZ26 | W1: =_xlfn.XLOOKUP(MAX(X4:X102), X4:X102, W4:W102) -> /FCPOF27 | Z1: =_xlfn.XLOOKUP(MAX(AA3:AA101), AA3:AA101, Z3:Z101) -> /DCPF7 | AC1: =_xlfn.XLOOKUP(MAX(AD3:AD101), AD3:AD101, AC3:AC101) -> /DSMF7 | AF1: =_xlfn.XLOOKUP(MAX(AG3:AG101), AG3:AG101, AF3:AF101) -> /DBYF7 | AI1: =_xlfn.XLOOKUP(MAX(AJ3:AJ101), AJ3:AJ101, AI3:AI101) -> /CRSMF7 | AL1: =_xlfn.XLOOKUP(MAX(AM3:AM101), AM3:AM101, AL3:AL101) -> /COIF7 | AO1: =_xlfn.XLOOKUP(MAX(AP3:AP101), AP3:AP101, AO3:AO101) -> /COMG7 | AR1: =_xlfn.XLOOKUP(MAX(AS3:AS101), AS3:AS101, AR3:AR101) -> /RSF7 | AU1: =_xlfn.XLOOKUP(MAX(AV3:AV101), AV3:AV101, AU3:AU101) -> /CUUV26 | AX1: =_xlfn.XLOOKUP(MAX(AY3:AY101), AY3:AY101, AX3:AX101) -> /HOZ26 | BA1: =_xlfn.XLOOKUP(MAX(BB4:BB102), BB4:BB102, BA4:BA102) -> /LGOZ6 | BD1: =_xlfn.XLOOKUP(MAX(BE3:BE101), BE3:BE101, BD3:BD101) -> /CLZ26 | BG1: =_xlfn.XLOOKUP(MAX(BH3:BH101), BH3:BH101, BG3:BG101) -> /RBZ26 | BJ1: =_xlfn.XLOOKUP(MAX(BK4:BK102), BK4:BK102, BJ4:BJ102) -> /LCOF7
A3: 0#W: | B3: =_xll.TR(A3,B2) -> /WZ26 | C3: =_xll.TR(B3:B15,"TR.OPENINTEREST",C2) -> 248802 | D3: 0#KW: | E3: =_xll.TR(D3,E2) -> /KWZ26 | F3: =_xll.TR(E3:E27,"TR.OPENINTEREST",F2) -> 146164 | G3: 0#MWE: | H3: =_xll.TR(G3,H2) -> /MWEZ26 | I3: =_xll.TR(H3:H27,"TR.OPENINTEREST",I2) -> 44066 | J3: 0#C: | K3: =_xll.TR(J3,K2) -> /CZ26 | L3: =_xll.TR(K3:K27,"TR.OPENINTEREST",L2) -> 782965 | M3: 0#S: | N3: =_xll.TR(M3,N2) -> /SX26 | O3: =_xll.TR(N3:N27,"TR.OPENINTEREST",O2) -> 191184 | P3: 0#SM: | Q3: =_xll.TR(P3,Q2) -> /SMZ26 | R3: =_xll.TR(Q3:Q27,"TR.OPENINTEREST",R2) -> 231259 | S3: 0#BO: | T3: =_xll.TR(S3,T2) -> /BOZ26 | U3: =_xll.TR(T3:T27,"TR.OPENINTEREST",U2) -> 202072 | V3: 0#FCPO: | W3: =_xll.TR(V3,W2) -> /FCPO-TOT | X3: =_xll.TR(W3:W27,"TR.OPENINTEREST",X2) -> 342738 | Y3: 0#DCP: | Z3: =_xll.TR(Y3,Z2) -> /DCPX6 | AA3: =_xll.TR(Z3:Z27,"TR.OPENINTEREST",AA2) -> 27873 | AB3: 0#DSM: | AC3: =_xll.TR(AB3,AC2) -> /DSMX6 | AD3: =_xll.TR(AC3:AC27,"TR.OPENINTEREST",AD2) -> 197055 | AE3: 0#DBY: | AF3: =_xll.TR(AE3,AF2) -> /DBYX6 | AG3: =_xll.TR(AF3:AF27,"TR.OPENINTEREST",AG2) -> 72868 | AH3: 0#CRSM: | AI3: =_xll.TR(AH3,AI2) -> /CRSMX6 | AJ3: =_xll.TR(AI3:AI27,"TR.OPENINTEREST",AJ2) -> 16974 | AK3: 0#COI: | AL3: =_xll.TR(AK3,AL2) -> /COIX6 | AM3: =_xll.TR(AL3:AL27,"TR.OPENINTEREST",AM2) -> 14740 | AN3: 0#COM: | AO3: =_xll.TR(AN3,AO2) -> /COMX6 | AP3: =_xll.TR(AO3:AO27,"TR.OPENINTEREST",AP2) -> 4363 | AQ3: 0#RS: | AR3: =_xll.TR(AQ3,AR2) -> /RSX6 | AS3: =_xll.TR(AR3:AR27,"TR.OPENINTEREST",AS2) -> 56219 | AT3: 0#CUU: | AU3: =_xll.TR(AT3,AU2) -> /CUUV26 | AV3: =_xll.TR(AU3:AU27,"TR.OPENINTEREST",AV2) -> 8455 | AW3: 0#HO: | AX3: =_xll.TR(AW3,AX2) -> /HOX26 | AY3: =_xll.TR(AX3:AX27,"TR.OPENINTEREST",AY2) -> 26757 | AZ3: 0#LGO: | BA3: =_xll.TR(AZ3,BA2) -> /LGOTOT | BB3: =_xll.TR(BA3:BA27,"TR.OPENINTEREST",BB2) -> 718887 | BC3: 0#CL: | BD3: =_xll.TR(BC3,BD2) -> /CLZ26 | BE3: =_xll.TR(BD3:BD27,"TR.OPENINTEREST",BE2) -> 312676 | BF3: 0#RB: | BG3: =_xll.TR(BF3,BG2) -> /RBX26 | BH3: =_xll.TR(BG3:BG27,"TR.OPENINTEREST",BH2) -> 31505 | BI3: 0#LCO: | BJ3: =_xll.TR(BI3,BJ2) -> /LCOTOT | BK3: =_xll.TR(BJ3:BJ27,"TR.OPENINTEREST",BK2) -> 2623750
B4: /WH27 | C4: 136249 | E4: /KWH27 | F4: 90754 | H4: /MWEH27 | I4: 21172 | K4: /CH27 | L4: 436845 | N4: /SF27 | O4: 331274 | Q4: /SMF27 | R4: 158202 | T4: /BOF27 | U4: 126000 | W4: /FCPOX26 | X4: 8506 | Z4: /DCPZ6 | AA4: 37917 | AC4: /DSMZ6 | AD4: 299087 | AF4: /DBYZ6 | AG4: 106390 | AI4: /CRSMF7 | AJ4: 683596 | AL4: /COIF7 | AM4: 374965 | AO4: /COMG7 | AP4: 108130 | AR4: /RSF7 | AS4: 158886 | AU4: /CUUX26 | AV4: 7912 | AX4: /HOZ26 | AY4: 67258 | BA4: /LGOX6 | BB4: 112300 | BD4: /CLF27 | BE4: 171998 | BG4: /RBZ26 | BH4: 107980 | BJ4: /LCOZ6 | BK4: 371648
B5: /WK27 | C5: 50668 | E5: /KWK27 | F5: 34249 | H5: /MWEK27 | I5: 4866 | K5: /CK27 | L5: 187222 | N5: /SH27 | O5: 199474 | Q5: /SMH27 | R5: 115067 | T5: /BOH27 | U5: 86329 | W5: /FCPOZ26 | X5: 50806 | Z5: /DCPF7 | AA5: 554091 | AC5: /DSMF7 | AD5: 2249050 | AF5: /DBYF7 | AG5: 536750 | AI5: /CRSMH7 | AJ5: 255496 | AL5: /COIH7 | AM5: 88115 | AO5: /COMK7 | AP5: 28814 | AR5: /RSH7 | AS5: 63775 | AU5: /CUUZ26 | AV5: 7702 | AX5: /HOF27 | AY5: 43321 | BA5: /LGOZ6 | BB5: 155578 | BD5: /CLG27 | BE5: 86797 | BG5: /RBF27 | BH5: 60260 | BJ5: /LCOF7 | BK5: 544488
B6: /WN27 | C6: 63921 | E6: /KWN27 | F6: 37748 | H6: /MWEN27 | I6: 1839 | K6: /CN27 | L6: 200777 | N6: /SK27 | O6: 117781 | Q6: /SMK27 | R6: 54105 | T6: /BOK27 | U6: 64272 | W6: /FCPOF27 | X6: 70502 | Z6: /DCPG7 | AA6: 37802 | AC6: /DSMH7 | AD6: 471970 | AF6: /DBYH7 | AG6: 116946 | AI6: /CRSMK7 | AJ6: 173623 | AL6: /COIK7 | AM6: 72105 | AO6: /COMQ7 | AP6: 15087 | AR6: /RSK7 | AS6: 26341 | AU6: /CUUF27 | AV6: 4923 | AX6: /HOG27 | AY6: 22538 | BA6: /LGOF7 | BB6: 104040 | BD6: /CLH27 | BE6: 103728 | BG6: /RBG27 | BH6: 28839 | BJ6: /LCOG7 | BK6: 222199
B7: /WU27 | C7: 11368 | E7: /KWU27 | F7: 8493 | H7: /MWEU27 | I7: 2073 | K7: /CU27 | L7: 74052 | N7: /SN27 | O7: 112701 | Q7: /SMN27 | R7: 40065 | T7: /BON27 | U7: 64252 | W7: /FCPOG27 | X7: 30486 | Z7: /DCPH7 | AA7: 38741 | AC7: /DSMK7 | AD7: 901528 | AF7: /DBYK7 | AG7: 281604 | AI7: /CRSMN7 | AJ7: 18458 | AL7: /COIN7 | AM7: 976 | AO7: /COMX7 | AP7: 2558 | AR7: /RSN7 | AS7: 10094 | AU7: /CUUG27 | AV7: 3735 | AX7: /HOH27 | AY7: 23372 | BA7: /LGOG7 | BB7: 45147 | BD7: /CLJ27 | BE7: 58852 | BG7: /RBH27 | BH7: 33156 | BJ7: /LCOH7 | BK7: 181192
B8: /WZ27 | C8: 13277 | E8: /KWZ27 | F8: 4511 | H8: /MWEZ27 | I8: 538 | K8: /CZ27 | L8: 125718 | N8: /SQ27 | O8: 9858 | Q8: /SMQ27 | R8: 6794 | T8: /BOQ27 | U8: 7748 | W8: /FCPOH27 | X8: 33084 | Z8: /DCPJ7 | AA8: 5901 | AC8: /DSMN7 | AD8: 271927 | AF8: /DBYN7 | AG8: 56280 | AI8: /CRSMQ7 | AJ8: 1555 | AL8: /COIU7 | AM8: 2406 | AO8: /COMG8 | AP8: 668 | AR8: /RSU7 | AS8: NULL | AU8: /CUUH27 | AV8: 3262 | AX8: /HOJ27 | AY8: 10744 | BA8: /LGOH7 | BB8: 56946 | BD8: /CLK27 | BE8: 48837 | BG8: /RBJ27 | BH8: 19246 | BJ8: /LCOJ7 | BK8: 83677
B9: /WH28 | C9: 1168 | E9: /KWH28 | F9: 351 | H9: /MWEH28 | I9: NULL | K9: /CH28 | L9: 10285 | N9: /SU27 | O9: 7502 | Q9: /SMU27 | R9: 4269 | T9: /BOU27 | U9: 3910 | W9: /FCPOJ27 | X9: 27583 | Z9: /DCPK7 | AA9: 370699 | AC9: /DSMQ7 | AD9: 85830 | AF9: /DBYQ7 | AG9: 30526 | AI9: /CRSMU7 | AJ9: 5417 | AO9: /COMK8 | AP9: 0 | AR9: /RSX7 | AS9: 9755 | AU9: /CUUJ27 | AV9: 1883 | AX9: /HOK27 | AY9: 7394 | BA9: /LGOJ7 | BB9: 32412 | BD9: /CLM27 | BE9: 127919 | BG9: /RBK27 | BH9: 12927 | BJ9: /LCOK7 | BK9: 83349
B10: /WK28 | C10: 234 | E10: /KWK28 | F10: 78 | H10: /MWEK28 | I10: NULL | K10: /CK28 | L10: 3852 | N10: /SX27 | O10: 69056 | Q10: /SMV27 | R10: 3196 | T10: /BOV27 | U10: 3598 | W10: /FCPOK27 | X10: 40031 | Z10: /DCPM7 | AA10: 222 | AC10: /DSMU7 | AD10: 87969 | AF10: /DBYU7 | AG10: 7909 | AO10: /COMQ8 | AP10: 0 | AR10: /RSF8 | AS10: 366 | AU10: /CUUK27 | AV10: 661 | AX10: /HOM27 | AY10: 22094 | BA10: /LGOK7 | BB10: 25781 | BD10: /CLN27 | BE10: 47314 | BG10: /RBM27 | BH10: 17524 | BJ10: /LCOM7 | BK10: 162710
B11: /WN28 | C11: 765 | E11: /KWN28 | F11: 159 | H11: /MWEN28 | I11: NULL | K11: /CN28 | L11: 4328 | N11: /SF28 | O11: 6233 | Q11: /SMZ27 | R11: 8815 | T11: /BOZ27 | U11: 12075 | W11: /FCPOM27 | X11: 17393 | Z11: /DCPN7 | AA11: 818 | AO11: /COMX8 | AP11: 0 | AR11: /RSH8 | AS11: NULL | AU11: /CUUM27 | AV11: 1405 | AX11: /HON27 | AY11: 5430 | BA11: /LGOM7 | BB11: 35717 | BD11: /CLQ27 | BE11: 41354 | BG11: /RBN27 | BH11: 8389 | BJ11: /LCON7 | BK11: 54700
B12: /WU28 | C12: 42 | E12: /KWU28 | F12: 4 | H12: /MWEU28 | I12: NULL | K12: /CU28 | L12: 1293 | N12: /SH28 | O12: 3436 | Q12: /SMF28 | R12: 761 | T12: /BOF28 | U12: 485 | W12: /FCPON27 | X12: 18441 | Z12: /DCPQ7 | AA12: 387 | AO12: /COMG9 | AP12: 0 | AR12: /RSK8 | AS12: NULL | AU12: /CUUN27 | AV12: 589 | AX12: /HOQ27 | AY12: 3824 | BA12: /LGON7 | BB12: 19038 | BD12: /CLU27 | BE12: 55034 | BG12: /RBQ27 | BH12: 3133 | BJ12: /LCOQ7 | BK12: 54050
B13: /WZ28 | C13: 595 | E13: /KWZ28 | F13: 2 | H13: /MWEZ28 | I13: NULL | K13: /CZ28 | L13: 3872 | N13: /SK28 | O13: 920 | Q13: /SMH28 | R13: 519 | T13: /BOH28 | U13: 238 | W13: /FCPOQ27 | X13: 9030 | Z13: /DCPU7 | AA13: 69597 | AR13: /RSN8 | AS13: NULL | AU13: /CUUQ27 | AV13: 156 | AX13: /HOU27 | AY13: 4327 | BA13: /LGOQ7 | BB13: 15340 | BD13: /CLV27 | BE13: 42130 | BG13: /RBU27 | BH13: 3213 | BJ13: /LCOU7 | BK13: 72109
B14: /WH29 | C14: 3 | E14: /KWH29 | F14: NULL | H14: /MWEH29 | I14: NULL | K14: /CN29 | L14: 12 | N14: /SN28 | O14: 964 | Q14: /SMK28 | R14: 379 | T14: /BOK28 | U14: 134 | W14: /FCPOU27 | X14: 17635 | Z14: /DCPV7 | AA14: 2 | AR14: /RSU8 | AS14: NULL | AU14: /CUUU27 | AV14: 375 | AX14: /HOV27 | AY14: 3052 | BA14: /LGOU7 | BB14: 17775 | BD14: /CLX27 | BE14: 48387 | BG14: /RBV27 | BH14: 2236 | BJ14: /LCOV7 | BK14: 44509
B15: /WK29 | C15: 2 | E15: /KWK29 | F15: NULL | H15: /MWEK29 | I15: NULL | K15: /CZ29 | L15: 117 | N15: /SQ28 | O15: 13 | Q15: /SMN28 | R15: 291 | T15: /BON28 | U15: 41 | W15: /FCPOV27 | X15: 1254 | AU15: /CUUV27 | AV15: 146 | AX15: /HOX27 | AY15: 2914 | BA15: /LGOV7 | BB15: 11428 | BD15: /CLZ27 | BE15: 188435 | BG15: /RBX27 | BH15: 1846 | BJ15: /LCOX7 | BK15: 42182
B16: /WN29 | E16: /KWN29 | F16: NULL | H16: /MWEN29 | I16: NULL | L16: 91 | N16: /SU28 | O16: 20 | Q16: /SMQ28 | R16: 127 | T16: /BOQ28 | U16: 5 | W16: /FCPOX27 | X16: 10793 | AU16: /CUUX27 | AV16: 138 | AX16: /HOZ27 | AY16: 11311 | BA16: /LGOX7 | BB16: 9197 | BD16: /CLF28 | BE16: 40100 | BG16: /RBZ27 | BH16: 5884 | BJ16: /LCOZ7 | BK16: 189513
F17: NULL | H17: /MWEU29 | I17: NULL | L17: 58 | N17: /SX28 | O17: 305 | Q17: /SMU28 | R17: 139 | T17: /BOU28 | U17: 10 | W17: /FCPOF28 | X17: 1818 | AU17: /CUUZ27 | AV17: 243 | AX17: /HOF28 | AY17: 2086 | BA17: /LGOZ7 | BB17: 36676 | BD17: /CLG28 | BE17: 23216 | BG17: /RBF28 | BH17: 1748 | BJ17: /LCOF8 | BK17: 42459
L18: 17 | N18: /SN29 | O18: 4 | Q18: /SMV28 | R18: 128 | T18: /BOV28 | U18: 1 | W18: /FCPOH28 | X18: 1459 | AU18: /CUUF28 | AV18: NULL | AX18: /HOG28 | AY18: 414 | BA18: /LGOF8 | BB18: 7448 | BD18: /CLH28 | BE18: 29892 | BG18: /RBG28 | BH18: 289 | BJ18: /LCOG8 | BK18: 38866
L19: 14 | N19: /SX29 | O19: 12 | Q19: /SMZ28 | R19: 62 | T19: /BOZ28 | U19: 27 | W19: /FCPOK28 | X19: 66 | AU19: /CUUG28 | AV19: NULL | AX19: /HOH28 | AY19: 736 | BA19: /LGOG8 | BB19: 2914 | BD19: /CLJ28 | BE19: 26391 | BG19: /RBH28 | BH19: 391 | BJ19: /LCOH8 | BK19: 28418
L20: NULL | O20: 8 | R20: 60 | U20: 27 | W20: /FCPON28 | X20: 1 | AU20: /CUUH28 | AV20: NULL | AX20: /HOJ28 | AY20: 246 | BA20: /LGOH8 | BB20: 5629 | BD20: /CLK28 | BE20: 13419 | BG20: /RBJ28 | BH20: 118 | BJ20: /LCOJ8 | BK20: 8150
O21: 4 | R21: NULL | U21: NULL | W21: /FCPOU28 | X21: 0 | AU21: /CUUJ28 | AV21: NULL | AX21: /HOK28 | AY21: 137 | BA21: /LGOJ8 | BB21: 1678 | BD21: /CLM28 | BE21: 56719 | BG21: /RBK28 | BH21: 27 | BJ21: /LCOK8 | BK21: 10127
O22: 4 | R22: NULL | U22: NULL | W22: /FCPOX28 | X22: NULL | AU22: /CUUK28 | AV22: NULL | AX22: /HOM28 | AY22: 989 | BA22: /LGOK8 | BB22: 792 | BD22: /CLN28 | BE22: 13506 | BG22: /RBM28 | BH22: 264 | BJ22: /LCOM8 | BK22: 85122
O23: 2 | R23: NULL | U23: NULL | W23: /FCPOF29 | X23: NULL | AU23: /CUUM28 | AV23: NULL | AX23: /HON28 | AY23: 110 | BA23: /LGOM8 | BB23: 7993 | BD23: /CLQ28 | BE23: 12527 | BG23: /RBN28 | BH23: 14 | BJ23: /LCON8 | BK23: 9595
O24: 3 | R24: NULL | U24: NULL | W24: /FCPOH29 | X24: NULL | AU24: /CUUN28 | AV24: NULL | AX24: /HOQ28 | AY24: 93 | BA24: /LGON8 | BB24: 781 | BD24: /CLU28 | BE24: 23128 | BG24: /RBQ28 | BH24: 7 | BJ24: /LCOQ8 | BK24: 7685
O25: NULL | R25: NULL | U25: NULL | W25: /FCPOK29 | X25: NULL | AU25: /CUUQ28 | AV25: NULL | AX25: /HOU28 | AY25: 90 | BA25: /LGOQ8 | BB25: 893 | BD25: /CLV28 | BE25: 9126 | BG25: /RBU28 | BH25: 7 | BJ25: /LCOU8 | BK25: 16389
R26: NULL | U26: NULL | W26: /FCPON29 | X26: NULL | AU26: /CUUU28 | AV26: NULL | AX26: /HOV28 | AY26: 84 | BA26: /LGOU8 | BB26: 717 | BD26: /CLX28 | BE26: 15664 | BG26: /RBV28 | BH26: 12 | BJ26: /LCOV8 | BK26: 7693
R27: NULL | U27: NULL | W27: /FCPOU29 | X27: NULL | AU27: /CUUV28 | AV27: NULL | AX27: /HOX28 | AY27: 87 | BA27: /LGOV8 | BB27: 358 | BD27: /CLZ28 | BE27: 125491 | BG27: /RBX28 | BH27: 13 | BJ27: /LCOX8 | BK27: 7986
AU28: /CUUX28 | AX28: /HOZ28 | BA28: /LGOX8 | BD28: /CLF29 | BG28: /RBZ28 | BJ28: /LCOZ8
AU29: /CUUZ28 | AX29: /HOF29 | BA29: /LGOZ8 | BD29: /CLG29 | BG29: /RBF29 | BJ29: /LCOF9
AU30: /CUUF29 | AX30: /HOG29 | BA30: /LGOF9 | BD30: /CLH29 | BG30: /RBG29 | BJ30: /LCOG9
AU31: /CUUG29 | AX31: /HOH29 | BA31: /LGOG9 | BD31: /CLJ29 | BG31: /RBH29 | BJ31: /LCOH9
AU32: /CUUH29 | AX32: /HOJ29 | BA32: /LGOH9 | BD32: /CLK29 | BG32: /RBJ29 | BJ32: /LCOJ9
AU33: /CUUJ29 | AX33: /HOK29 | BA33: /LGOJ9 | BD33: /CLM29 | BG33: /RBK29 | BJ33: /LCOK9
AU34: /CUUK29 | AX34: /HOM29 | BA34: /LGOK9 | BD34: /CLN29 | BG34: /RBM29 | BJ34: /LCOM9
AU35: /CUUM29 | AX35: /HON29 | BA35: /LGOM9 | BD35: /CLQ29 | BG35: /RBN29 | BJ35: /LCON9
AU36: /CUUN29 | AX36: /HOQ29 | BA36: /LGON9 | BD36: /CLU29 | BG36: /RBQ29 | BJ36: /LCOQ9
AU37: /CUUQ29 | AX37: /HOU29 | BA37: /LGOQ9 | BD37: /CLV29 | BG37: /RBU29 | BJ37: /LCOU9
AU38: /CUUU29 | AX38: /HOV29 | BA38: /LGOU9 | BD38: /CLX29 | BG38: /RBV29 | BJ38: /LCOV9
AX39: /HOX29 | BA39: /LGOV9 | BD39: /CLZ29 | BG39: /RBX29 | BJ39: /LCOX9
AX40: /HOZ29 | BA40: /LGOX9 | BD40: /CLF30 | BG40: /RBZ29 | BJ40: /LCOZ9
AX41: /HOF30 | BA41: /LGOZ9 | BD41: /CLG30 | BG41: /RBF30 | BJ41: /LCOF0
...

Sheet DataBackup
A1: 260
B2: =_xll.RHistory(B5:B35,".Timestamp;.Close","NBROWS:"&$A$1&" INTERVAL:1D",,"TSREPEAT:NO CH:Fd",C3) -> Updated at 17:18:37 | D2: {=TRANSPOSE(B5:B23)} -> /WZ26 | E2: /KWZ26 | F2: /MWEZ26 | G2: /CZ26 | H2: /SF27 | I2: /SMZ26 | J2: /BOZ26 | K2: /FCPOF27 | L2: /DCPF7 | M2: /DSMF7 | N2: /DBYF7 | O2: /CRSMF7 | P2: /COIF7 | Q2: /COMG7 | R2: /RSF7 | S2: /CUUV26 | T2: /HOZ26 | U2: /LGOZ6 | V2: /CLZ26
C3: Timestamp | D3: Trade Close | E3: Trade Close | F3: Trade Close | G3: Trade Close | H3: Trade Close | I3: Trade Close | J3: Trade Close | K3: Trade Close | L3: Trade Close | M3: Trade Close | N3: Trade Close | O3: Trade Close | P3: Trade Close | Q3: Trade Close | R3: Trade Close | S3: Trade Close | T3: Trade Close | U3: Trade Close | V3: Trade Close | BC3: 4067 | BE3: 4067 | BG3: 4067
C4: 46318 | D4: 626.75 | E4: 666.75 | F4: 6.4725 | G4: 459 | H4: 1265.25 | I4: 347.9 | J4: 66.75 | K4: 4827 | L4: 9567 | M4: 3272 | N4: 9080 | O4: 2251 | P4: 10337 | Q4: 549 | R4: 792.1 | T4: 4.7758 | U4: 1429 | V4: 100.31
B5: =Instrument!B1 -> /WZ26 | C5: 46317 | D5: 624.75 | E5: 665.75 | F5: 6.4175 | G5: 460.5 | H5: 1264.75 | I5: 347.3 | J5: 66.74 | K5: 4792 | L5: 9579 | M5: 3240 | N5: 8943 | O5: 2254 | P5: 10212 | Q5: 547.25 | R5: 791.3 | S5: 2.0425 | T5: 4.7366 | U5: 1393.75 | V5: 99.47
B6: =Instrument!E1 -> /KWZ26 | C6: 46316 | D6: 628.25 | E6: 673 | F6: 6.515 | G6: 463.25 | H6: 1258.25 | I6: 348.3 | J6: 65.97 | K6: 4767 | L6: 9614 | M6: 3263 | N6: 8917 | O6: 2268 | P6: 10231 | Q6: 540.25 | R6: 785.5 | S6: 2.06 | T6: 4.5772 | U6: 1379.25 | V6: 97.15
B7: =Instrument!H1 -> /MWEZ26 | C7: 46315 | D7: 643.25 | E7: 691 | F7: 6.6175 | G7: 462 | H7: 1263.5 | I7: 348.7 | J7: 66.73 | K7: 4817 | L7: 9523 | M7: 3277 | N7: 8891 | O7: 2299 | P7: 10295 | Q7: 545 | R7: 793.9 | S7: 2.07 | T7: 4.7141 | U7: 1400.5 | V7: 97.82
B8: =Instrument!K1 -> /CZ26 | C8: 46314 | D8: 655.25 | E8: 699.5 | F8: 6.7 | G8: 467 | H8: 1268.75 | I8: 354.8 | J8: 66.69 | K8: 4766 | L8: 9499 | M8: 3277 | N8: 8874 | O8: 2350 | P8: 10274 | Q8: 546.5 | R8: 800.2 | S8: 2.0875 | T8: 4.726 | U8: 1402.25 | V8: 98.54
B9: =Instrument!N1 -> /SF27 | C9: 46311 | D9: 660.5 | E9: 704 | F9: 6.765 | G9: 474.25 | H9: 1275.75 | I9: 357.1 | J9: 67.13 | K9: 4769 | L9: 9418 | M9: 3299 | N9: 8834 | O9: 2345 | P9: 10311 | Q9: 552 | R9: 811.6 | S9: 2.1 | T9: 4.7232 | U9: 1369.5 | V9: 99.02
B10: =Instrument!Q1 -> /SMZ26 | C10: 46310 | D10: 670 | E10: 713 | F10: 6.86 | G10: 478 | H10: 1277.75 | I10: 359.8 | J10: 67.15 | K10: 4725 | L10: 9566 | M10: 3340 | N10: 8921 | O10: 2370 | P10: 10318 | Q10: 554.75 | R10: 813.7 | S10: 2.095 | T10: 4.6545 | U10: 1386.75 | V10: 96.5
B11: =Instrument!T1 -> /BOZ26 | C11: 46309 | D11: 673.25 | E11: 715 | F11: 6.9 | G11: 480.75 | H11: 1292 | I11: 364.5 | J11: 67.06 | K11: 4810 | L11: 9741 | M11: 3373 | N11: 9033 | O11: 2393 | P11: 10459 | Q11: 559.25 | R11: 824.6 | S11: 2.075 | T11: 4.7508 | U11: 1404 | V11: 93.9
B12: =Instrument!W1 -> /FCPOF27 | C12: 46308 | D12: 669.25 | E12: 712.25 | F12: 6.94 | G12: 482.75 | H12: 1300 | I12: 363.2 | J12: 68.02 | K12: 4787 | L12: 9639 | M12: 3373 | N12: 8962 | O12: 2378 | P12: 10394 | Q12: 559.25 | R12: 826.6 | S12: 2.09 | T12: 4.7766 | U12: 1410.75 | V12: 93.17
B13: =Instrument!Z1 -> /DCPF7 | C13: 46307 | D13: 672.25 | E13: 715.25 | F13: 6.9625 | G13: 483 | H13: 1304.75 | I13: 368.7 | J13: 68.63 | K13: 4758 | L13: 9700 | M13: 3383 | N13: 9008 | O13: 2368 | P13: 10374 | Q13: 552.25 | S13: 2.11 | T13: 4.5868 | U13: 1371.25 | V13: 92.86
B14: =Instrument!AC1 -> /DSMF7 | C14: 46304 | D14: 671 | E14: 719.25 | F14: 6.9525 | G14: 479.75 | H14: 1308.75 | I14: 365.6 | J14: 68.02 | K14: 4709 | L14: 9662 | M14: 3389 | N14: 8995 | O14: 2365 | P14: 10301 | Q14: 555.75 | R14: 829.8 | S14: 2.0675 | T14: 4.5884 | U14: 1376 | V14: 91.01
B15: =Instrument!AF1 -> /DBYF7 | C15: 46303 | D15: 683.25 | E15: 736.25 | F15: 7.06 | G15: 500.25 | H15: 1304.25 | I15: 357.6 | J15: 67.92 | K15: 4767 | L15: 9564 | M15: 3388 | N15: 8933 | O15: 2352 | P15: 10277 | Q15: 557.25 | R15: 828.9 | S15: 2.085 | T15: 4.7165 | U15: 1391.25 | V15: 90.75
B16: =Instrument!AI1 -> /CRSMF7 | C16: 46302 | D16: 686.5 | E16: 738.5 | F16: 7.1025 | G16: 502 | H16: 1314.5 | I16: 365.8 | J16: 67.68 | K16: 4636 | Q16: 552.75 | R16: 822.9 | S16: 2.07 | T16: 4.4766 | U16: 1333 | V16: 87.55
B17: =Instrument!AL1 -> /COIF7 | C17: 46301 | D17: 704.25 | E17: 756.25 | F17: 7.1975 | G17: 508 | H17: 1319.25 | I17: 354.8 | J17: 69.91 | K17: 4663 | Q17: 561 | R17: 839 | S17: 2.08 | T17: 4.4231 | U17: 1257 | V17: 88.43
B18: =Instrument!AO1 -> /COMG7 | C18: 46300 | D18: 692.25 | E18: 742.25 | F18: 7.085 | G18: 497.25 | H18: 1297.5 | I18: 347.1 | J18: 69.35 | K18: 4672 | Q18: 558 | R18: 832.8 | S18: 2.055 | T18: 4.4001 | U18: 1301.5 | V18: 88.2
B19: =Instrument!AR1 -> /RSF7 | C19: 46297 | D19: 683 | E19: 735.25 | F19: 6.98 | G19: 497.75 | H19: 1294.5 | I19: 347.5 | J19: 68.62 | K19: 4627 | Q19: 555.25 | R19: 828.7 | S19: 2.1 | T19: 4.3573 | U19: 1265.5 | V19: 89.43
B20: =Instrument!AU1 -> /CUUV26 | C20: 46296 | D20: 682.75 | E20: 737.5 | F20: 6.9675 | G20: 502.25 | H20: 1300.75 | I20: 353.3 | J20: 67.38 | K20: 4652 | Q20: 551.75 | R20: 825.2 | S20: 2.115 | T20: 4.4906 | U20: 1335.75 | V20: 90.84
B21: =Instrument!AX1 -> /HOZ26 | C21: 46295 | D21: 675.75 | E21: 733 | F21: 6.9325 | G21: 500.75 | H21: 1309.25 | I21: 356.9 | J21: 68.28 | K21: 4717 | L21: 9593 | M21: 3369 | N21: 8934 | O21: 2332 | P21: 10217 | Q21: 554 | S21: 2.14 | T21: 4.5068 | U21: 1350.25 | V21: 88.42
B22: =Instrument!BA1 -> /LGOZ6 | C22: 46294 | D22: 692.75 | E22: 743 | F22: 6.9925 | G22: 522 | H22: 1312.75 | I22: 359 | J22: 68.36 | K22: 4731 | L22: 9571 | M22: 3347 | N22: 8855 | O22: 2298 | P22: 10044 | Q22: 557.75 | R22: 837.1 | S22: 2.145 | T22: 4.3323 | U22: 1297.25 | V22: 87.25
B23: =Instrument!BD1 -> /CLZ26 | C23: 46293 | D23: 688.75 | E23: 745.75 | F23: 7.0175 | G23: 523 | H23: 1303 | I23: 359.4 | J23: 67.66 | K23: 4774 | L23: 9675 | M23: 3386 | N23: 8883 | O23: 2337 | P23: 10134 | Q23: 548.25 | R23: 821.8 | S23: 2.185 | T23: 4.3681 | U23: 1336.75 | V23: 89.01
C24: 46290 | D24: 703.25 | E24: 762 | F24: 7.135 | G24: 528.25 | H24: 1332.5 | I24: 371 | J24: 67.84 | K24: 4768 | Q24: 557.5 | R24: 841.4 | S24: 2.21 | T24: 4.3746 | U24: 1346.25 | V24: 88.71
C25: 46289 | D25: 707 | E25: 767 | F25: 7.2025 | G25: 527.5 | H25: 1332 | I25: 372.4 | J25: 67.55 | K25: 4870 | L25: 9787 | M25: 3405 | N25: 8943 | O25: 2347 | P25: 10236 | Q25: 557.75 | R25: 841.2 | S25: 2.18 | T25: 4.4197 | U25: 1385.5 | V25: 90.9
C26: 46288 | D26: 708.5 | E26: 771.75 | F26: 7.2875 | G26: 529 | H26: 1333.75 | I26: 370.6 | J26: 67.81 | K26: 4851 | L26: 9740 | M26: 3414 | N26: 8927 | O26: 2361 | P26: 10145 | Q26: 561.75 | R26: 837.2 | S26: 2.175 | T26: 4.5171 | U26: 1344 | V26: 89.51
C27: 46287 | D27: 717.25 | E27: 781.25 | F27: 7.3625 | G27: 536.75 | H27: 1341.25 | I27: 370.7 | J27: 67.92 | K27: 4884 | L27: 9859 | M27: 3410 | N27: 8946 | O27: 2362 | P27: 10243 | Q27: 560 | R27: 836.1 | S27: 2.185 | T27: 4.5489 | U27: 1311 | V27: 87.98
C28: 46286 | D28: 726.75 | E28: 794.5 | F28: 7.4625 | G28: 543 | H28: 1344 | I28: 368.4 | J28: 68.85 | K28: 4929 | L28: 9876 | M28: 3391 | N28: 8897 | O28: 2347 | P28: 10186 | Q28: 563.25 | R28: 846.8 | S28: 2.19 | T28: 4.4851 | U28: 1305.75 | V28: 89.16
C29: 46283 | D29: 714.25 | E29: 783.75 | F29: 7.4125 | G29: 527.5 | H29: 1320 | I29: 358.6 | J29: 68.22 | K29: 4983 | L29: 9907 | M29: 3429 | N29: 8905 | O29: 2389 | P29: 10113 | Q29: 557.25 | R29: 833 | S29: 2.16 | T29: 4.5875 | U29: 1351.75 | V29: 92.05
C30: 46282 | D30: 727 | E30: 794.5 | F30: 7.525 | G30: 530.5 | H30: 1337 | I30: 371.3 | J30: 69.15 | K30: 5028 | L30: 10070 | M30: 3480 | N30: 9017 | O30: 2421 | P30: 10211 | Q30: 556 | R30: 844.1 | S30: 2.135 | T30: 4.6262 | U30: 1338.25 | V30: 92.61
C31: 46281 | D31: 730.75 | E31: 799.5 | F31: 7.56 | G31: 534.25 | H31: 1337.25 | I31: 365.6 | J31: 69.67 | L31: 10066 | M31: 3434 | N31: 9000 | O31: 2372 | P31: 10169 | Q31: 556.75 | R31: 837.8 | S31: 2.105 | T31: 4.7155 | U31: 1364 | V31: 92.79
C32: 46280 | D32: 728.5 | E32: 796.25 | F32: 7.485 | G32: 535.75 | H32: 1335.25 | I32: 365.4 | J32: 70.35 | K32: 5086 | L32: 10031 | M32: 3374 | N32: 8960 | O32: 2330 | P32: 10101 | Q32: 558.5 | R32: 840.9 | S32: 2.105 | T32: 4.7352 | U32: 1391.75 | V32: 95.51
C33: 46279 | D33: 722 | E33: 792.5 | F33: 7.3625 | G33: 533.25 | H33: 1320.25 | I33: 356.2 | J33: 70.19 | K33: 5052 | L33: 10038 | M33: 3384 | N33: 9024 | O33: 2349 | P33: 10192 | Q33: 555.5 | R33: 834.3 | S33: 2.07 | T33: 4.54 | U33: 1320.25 | V33: 92.6
C34: 46276 | D34: 725.25 | E34: 798.5 | F34: 7.45 | G34: 530.25 | H34: 1312 | I34: 352.8 | J34: 69.68 | K34: 5056 | L34: 10151 | M34: 3422 | N34: 9103 | O34: 2369 | P34: 10226 | Q34: 553 | R34: 827.1 | S34: 2.065 | T34: 4.5584 | U34: 1320.5 | V34: 91.43
C35: 46275 | D35: 741.25 | E35: 818.75 | F35: 7.625 | G35: 533.75 | H35: 1347.25 | I35: 356.9 | J35: 71.92 | K35: 5154 | L35: 10177 | M35: 3399 | N35: 9054 | O35: 2358 | P35: 10248 | Q35: 559.25 | R35: 849.4 | S35: 2.06 | T35: 4.6271 | U35: 1323.25 | V35: 93.93
C36: 46274 | D36: 728.75 | E36: 806.25 | F36: 7.48 | G36: 527.75 | H36: 1325.25 | I36: 351.4 | J36: 70.57 | K36: 5220 | L36: 10306 | M36: 3397 | N36: 9122 | O36: 2376 | P36: 10392 | Q36: 559 | R36: 841.2 | S36: 2.03 | T36: 4.4346 | U36: 1257.75 | V36: 89.32
C37: 46273 | D37: 747 | E37: 819 | F37: 7.54 | G37: 533.5 | H37: 1332 | I37: 349.8 | J37: 70.7 | K37: 5224 | L37: 10421 | M37: 3415 | N37: 9210 | O37: 2398 | P37: 10377 | Q37: 558.75 | R37: 848.3 | S37: 2.055 | T37: 4.2527 | U37: 1225 | V37: 87.14
C38: 46272 | K38: 5214 | L38: 10264 | M38: 3404 | N38: 9142 | O38: 2400 | P38: 10238 | Q38: 556.5 | U38: 1237.25
C39: 46269 | D39: 734 | E39: 802.25 | F39: 7.45 | G39: 536.75 | H39: 1325 | I39: 355.1 | J39: 69.27 | K39: 5155 | L39: 10212 | M39: 3402 | N39: 9144 | O39: 2397 | P39: 10152 | Q39: 553.5 | R39: 832.7 | S39: 2.08 | T39: 4.2091 | U39: 1200 | V39: 85.46
C40: 46268 | D40: 754.25 | E40: 815.5 | F40: 7.655 | G40: 540.75 | H40: 1331.5 | I40: 355.5 | J40: 70.04 | K40: 5107 | L40: 10270 | M40: 3386 | N40: 9182 | O40: 2393 | P40: 10226 | Q40: 553 | R40: 839.5 | S40: 2.095 | T40: 4.2399 | U40: 1218.5 | V40: 84.79
...

Sheet Data
A1: 260
B2: =_xll.RHistory(B5:B35,".Timestamp;.Close","NBROWS:"&$A$1&" INTERVAL:1D",,"TSREPEAT:NO CH:Fd",C4) -> Updated at 17:18:37 | C2: Column1 | D2: Column2 | E2: Column3 | F2: Column4 | G2: Column5 | H2: Column6 | I2: Column7 | J2: Column8 | K2: Column9 | L2: Column10 | M2: Column11 | N2: Column12 | O2: Column13 | P2: Column14 | Q2: Column15 | R2: Column16 | S2: Column17 | T2: Column18 | U2: Column19 | V2: Column20 | W2: Column21 | X2: Column22
D3: /WZ25 | E3: /KWZ25 | F3: /MWEZ25 | G3: /CZ25 | H3: /SF26 | I3: /SMZ25 | J3: /BOZ25 | K3: /FCPOF26 | L3: /DCPF6 | M3: /DSMF6 | N3: /DBYF6 | O3: /CRSMF6 | P3: /COIF6 | Q3: /COMG6 | R3: /RSF6 | S3: /CUUZ25 | T3: /HOZ25 | U3: /LGOZ5 | V3: /CLF26 | W3: /LCOJ6 | X3: /RBG26
C4: Timestamp | D4: Trade Close | E4: Trade Close | F4: Trade Close | G4: Trade Close | H4: Trade Close | I4: Trade Close | J4: Trade Close | K4: Trade Close | L4: Trade Close | M4: Trade Close | N4: Trade Close | O4: Trade Close | P4: Trade Close | Q4: Trade Close | R4: Trade Close | S4: Trade Close | T4: Trade Close | U4: Trade Close | V4: Trade Close | W4: Trade Close | X4: Trade Close
B5: =Instrument!B1 -> /WZ26 | C5: 46318 | D5: 626.75 | E5: 666.75 | F5: 6.4725 | G5: 459 | H5: 1265.25 | I5: 347.9 | J5: 66.75 | K5: 4827 | L5: 9567 | M5: 3272 | N5: 9080 | O5: 2251 | P5: 10337 | Q5: 549 | R5: 792.1 | T5: 4.7758 | U5: 1429 | V5: 100.31 | W5: 109.23 | X5: 3.1071
B6: =Instrument!E1 -> /KWZ26 | C6: 46317 | D6: 624.75 | E6: 665.75 | F6: 6.4175 | G6: 460.5 | H6: 1264.75 | I6: 347.3 | J6: 66.74 | K6: 4792 | L6: 9579 | M6: 3240 | N6: 8943 | O6: 2254 | P6: 10212 | Q6: 547.25 | R6: 791.3 | S6: 2.0425 | T6: 4.7366 | U6: 1393.75 | V6: 99.47 | W6: 108.66 | X6: 3.0893
B7: =Instrument!H1 -> /MWEZ26 | C7: 46316 | D7: 628.25 | E7: 673 | F7: 6.515 | G7: 463.25 | H7: 1258.25 | I7: 348.3 | J7: 65.97 | K7: 4767 | L7: 9614 | M7: 3263 | N7: 8917 | O7: 2268 | P7: 10231 | Q7: 540.25 | R7: 785.5 | S7: 2.06 | T7: 4.5772 | U7: 1379.25 | V7: 97.15 | W7: 105.07 | X7: 3.039
B8: =Instrument!K1 -> /CZ26 | C8: 46315 | D8: 643.25 | E8: 691 | F8: 6.6175 | G8: 462 | H8: 1263.5 | I8: 348.7 | J8: 66.73 | K8: 4817 | L8: 9523 | M8: 3277 | N8: 8891 | O8: 2299 | P8: 10295 | Q8: 545 | R8: 793.9 | S8: 2.07 | T8: 4.7141 | U8: 1400.5 | V8: 97.82 | W8: 105.1 | X8: 3.0441
B9: =Instrument!N1 -> /SF27 | C9: 46314 | D9: 655.25 | E9: 699.5 | F9: 6.7 | G9: 467 | H9: 1268.75 | I9: 354.8 | J9: 66.69 | K9: 4766 | L9: 9499 | M9: 3277 | N9: 8874 | O9: 2350 | P9: 10274 | Q9: 546.5 | R9: 800.2 | S9: 2.0875 | T9: 4.726 | U9: 1402.25 | V9: 98.54 | W9: 106.07 | X9: 3.1047
B10: =Instrument!Q1 -> /SMZ26 | C10: 46311 | D10: 660.5 | E10: 704 | F10: 6.765 | G10: 474.25 | H10: 1275.75 | I10: 357.1 | J10: 67.13 | K10: 4769 | L10: 9418 | M10: 3299 | N10: 8834 | O10: 2345 | P10: 10311 | Q10: 552 | R10: 811.6 | S10: 2.1 | T10: 4.7232 | U10: 1369.5 | V10: 99.02 | W10: 106.82 | X10: 3.1443
B11: =Instrument!T1 -> /BOZ26 | C11: 46310 | D11: 670 | E11: 713 | F11: 6.86 | G11: 478 | H11: 1277.75 | I11: 359.8 | J11: 67.15 | K11: 4725 | L11: 9566 | M11: 3340 | N11: 8921 | O11: 2370 | P11: 10318 | Q11: 554.75 | R11: 813.7 | S11: 2.095 | T11: 4.6545 | U11: 1386.75 | V11: 96.5 | W11: 103.17 | X11: 3.0798
B12: =Instrument!W1 -> /FCPOF27 | C12: 46309 | D12: 673.25 | E12: 715 | F12: 6.9 | G12: 480.75 | H12: 1292 | I12: 364.5 | J12: 67.06 | K12: 4810 | L12: 9741 | M12: 3373 | N12: 9033 | O12: 2393 | P12: 10459 | Q12: 559.25 | R12: 824.6 | S12: 2.075 | T12: 4.7508 | U12: 1404 | V12: 93.9 | W12: 103.4 | X12: 3.142
B13: =Instrument!Z1 -> /DCPF7 | C13: 46308 | D13: 669.25 | E13: 712.25 | F13: 6.94 | G13: 482.75 | H13: 1300 | I13: 363.2 | J13: 68.02 | K13: 4787 | L13: 9639 | M13: 3373 | N13: 8962 | O13: 2378 | P13: 10394 | Q13: 559.25 | R13: 826.6 | S13: 2.09 | T13: 4.7766 | U13: 1410.75 | V13: 93.17 | W13: 102.91 | X13: 3.1338
B14: =Instrument!AC1 -> /DSMF7 | C14: 46307 | D14: 672.25 | E14: 715.25 | F14: 6.9625 | G14: 483 | H14: 1304.75 | I14: 368.7 | J14: 68.63 | K14: 4758 | L14: 9700 | M14: 3383 | N14: 9008 | O14: 2368 | P14: 10374 | Q14: 552.25 | S14: 2.11 | T14: 4.5868 | U14: 1371.25 | V14: 92.86 | W14: 103.2 | X14: 3.1706
B15: =Instrument!AF1 -> /DBYF7 | C15: 46304 | D15: 671 | E15: 719.25 | F15: 6.9525 | G15: 479.75 | H15: 1308.75 | I15: 365.6 | J15: 68.02 | K15: 4709 | L15: 9662 | M15: 3389 | N15: 8995 | O15: 2365 | P15: 10301 | Q15: 555.75 | R15: 829.8 | S15: 2.0675 | T15: 4.5884 | U15: 1376 | V15: 91.01 | W15: 101.25 | X15: 3.1534
B16: =Instrument!AI1 -> /CRSMF7 | C16: 46303 | D16: 683.25 | E16: 736.25 | F16: 7.06 | G16: 500.25 | H16: 1304.25 | I16: 357.6 | J16: 67.92 | K16: 4767 | L16: 9564 | M16: 3388 | N16: 8933 | O16: 2352 | P16: 10277 | Q16: 557.25 | R16: 828.9 | S16: 2.085 | T16: 4.7165 | U16: 1391.25 | V16: 90.75 | W16: 100.96 | X16: 3.1596
B17: =Instrument!AL1 -> /COIF7 | C17: 46302 | D17: 686.5 | E17: 738.5 | F17: 7.1025 | G17: 502 | H17: 1314.5 | I17: 365.8 | J17: 67.68 | K17: 4636 | Q17: 552.75 | R17: 822.9 | S17: 2.07 | T17: 4.4766 | U17: 1333 | V17: 87.55 | W17: 97.45 | X17: 3.0711
B18: =Instrument!AO1 -> /COMG7 | C18: 46301 | D18: 704.25 | E18: 756.25 | F18: 7.1975 | G18: 508 | H18: 1319.25 | I18: 354.8 | J18: 69.91 | K18: 4663 | Q18: 561 | R18: 839 | S18: 2.08 | T18: 4.4231 | U18: 1257 | V18: 88.43 | W18: 97.59 | X18: 3.088
B19: =Instrument!AR1 -> /RSF7 | C19: 46300 | D19: 692.25 | E19: 742.25 | F19: 7.085 | G19: 497.25 | H19: 1297.5 | I19: 347.1 | J19: 69.35 | K19: 4672 | Q19: 558 | R19: 832.8 | S19: 2.055 | T19: 4.4001 | U19: 1301.5 | V19: 88.2 | W19: 97.58 | X19: 3.0719
B20: =Instrument!AU1 -> /CUUV26 | C20: 46297 | D20: 683 | E20: 735.25 | F20: 6.98 | G20: 497.75 | H20: 1294.5 | I20: 347.5 | J20: 68.62 | K20: 4627 | Q20: 555.25 | R20: 828.7 | S20: 2.1 | T20: 4.3573 | U20: 1265.5 | V20: 89.43 | W20: 98.71 | X20: 3.1119
B21: =Instrument!AX1 -> /HOZ26 | C21: 46296 | D21: 682.75 | E21: 737.5 | F21: 6.9675 | G21: 502.25 | H21: 1300.75 | I21: 353.3 | J21: 67.38 | K21: 4652 | Q21: 551.75 | R21: 825.2 | S21: 2.115 | T21: 4.4906 | U21: 1335.75 | V21: 90.84 | W21: 98.43 | X21: 3.1729
B22: =Instrument!BA1 -> /LGOZ6 | C22: 46295 | D22: 675.75 | E22: 733 | F22: 6.9325 | G22: 500.75 | H22: 1309.25 | I22: 356.9 | J22: 68.28 | K22: 4717 | L22: 9593 | M22: 3369 | N22: 8934 | O22: 2332 | P22: 10217 | Q22: 554 | S22: 2.14 | T22: 4.5068 | U22: 1350.25 | V22: 88.42 | W22: 95.09 | X22: 3.0472
B23: =Instrument!BD1 -> /CLZ26 | C23: 46294 | D23: 692.75 | E23: 743 | F23: 6.9925 | G23: 522 | H23: 1312.75 | I23: 359 | J23: 68.36 | K23: 4731 | L23: 9571 | M23: 3347 | N23: 8855 | O23: 2298 | P23: 10044 | Q23: 557.75 | R23: 837.1 | S23: 2.145 | T23: 4.3323 | U23: 1297.25 | V23: 87.25 | W23: 93.51 | X23: 2.9459
B24: =Instrument!BJ1 -> /LCOF7 | C24: 46293 | D24: 688.75 | E24: 745.75 | F24: 7.0175 | G24: 523 | H24: 1303 | I24: 359.4 | J24: 67.66 | K24: 4774 | L24: 9675 | M24: 3386 | N24: 8883 | O24: 2337 | P24: 10134 | Q24: 548.25 | R24: 821.8 | S24: 2.185 | T24: 4.3681 | U24: 1336.75 | V24: 89.01 | W24: 94.4 | X24: 2.968
B25: =Instrument!BG1 -> /RBZ26 | C25: 46290 | D25: 703.25 | E25: 762 | F25: 7.135 | G25: 528.25 | H25: 1332.5 | I25: 371 | J25: 67.84 | K25: 4768 | Q25: 557.5 | R25: 841.4 | S25: 2.21 | T25: 4.3746 | U25: 1346.25 | V25: 88.71 | W25: 94.11 | X25: 2.9827
C26: 46289 | D26: 707 | E26: 767 | F26: 7.2025 | G26: 527.5 | H26: 1332 | I26: 372.4 | J26: 67.55 | K26: 4870 | L26: 9787 | M26: 3405 | N26: 8943 | O26: 2347 | P26: 10236 | Q26: 557.75 | R26: 841.2 | S26: 2.18 | T26: 4.4197 | U26: 1385.5 | V26: 90.9 | W26: 96.42 | X26: 3.095
C27: 46288 | D27: 708.5 | E27: 771.75 | F27: 7.2875 | G27: 529 | H27: 1333.75 | I27: 370.6 | J27: 67.81 | K27: 4851 | L27: 9740 | M27: 3414 | N27: 8927 | O27: 2361 | P27: 10145 | Q27: 561.75 | R27: 837.2 | S27: 2.175 | T27: 4.5171 | U27: 1344 | V27: 89.51 | W27: 95.03 | X27: 3.0751
C28: 46287 | D28: 717.25 | E28: 781.25 | F28: 7.3625 | G28: 536.75 | H28: 1341.25 | I28: 370.7 | J28: 67.92 | K28: 4884 | L28: 9859 | M28: 3410 | N28: 8946 | O28: 2362 | P28: 10243 | Q28: 560 | R28: 836.1 | S28: 2.185 | T28: 4.5489 | U28: 1311 | V28: 87.98 | W28: 92.74 | X28: 2.9699
C29: 46286 | D29: 726.75 | E29: 794.5 | F29: 7.4625 | G29: 543 | H29: 1344 | I29: 368.4 | J29: 68.85 | K29: 4929 | L29: 9876 | M29: 3391 | N29: 8897 | O29: 2347 | P29: 10186 | Q29: 563.25 | R29: 846.8 | S29: 2.19 | T29: 4.4851 | U29: 1305.75 | V29: 89.16 | W29: 93.4 | X29: 2.9445
C30: 46283 | D30: 714.25 | E30: 783.75 | F30: 7.4125 | G30: 527.5 | H30: 1320 | I30: 358.6 | J30: 68.22 | K30: 4983 | L30: 9907 | M30: 3429 | N30: 8905 | O30: 2389 | P30: 10113 | Q30: 557.25 | R30: 833 | S30: 2.16 | T30: 4.5875 | U30: 1351.75 | V30: 92.05 | W30: 96.03 | X30: 3.0015
C31: 46282 | D31: 727 | E31: 794.5 | F31: 7.525 | G31: 530.5 | H31: 1337 | I31: 371.3 | J31: 69.15 | K31: 5028 | L31: 10070 | M31: 3480 | N31: 9017 | O31: 2421 | P31: 10211 | Q31: 556 | R31: 844.1 | S31: 2.135 | T31: 4.6262 | U31: 1338.25 | V31: 92.61 | W31: 96.15 | X31: 2.9994
C32: 46281 | D32: 730.75 | E32: 799.5 | F32: 7.56 | G32: 534.25 | H32: 1337.25 | I32: 365.6 | J32: 69.67 | L32: 10066 | M32: 3434 | N32: 9000 | O32: 2372 | P32: 10169 | Q32: 556.75 | R32: 837.8 | S32: 2.105 | T32: 4.7155 | U32: 1364 | V32: 92.79 | W32: 96.69 | X32: 2.9871
C33: 46280 | D33: 728.5 | E33: 796.25 | F33: 7.485 | G33: 535.75 | H33: 1335.25 | I33: 365.4 | J33: 70.35 | K33: 5086 | L33: 10031 | M33: 3374 | N33: 8960 | O33: 2330 | P33: 10101 | Q33: 558.5 | R33: 840.9 | S33: 2.105 | T33: 4.7352 | U33: 1391.75 | V33: 95.51 | W33: 98.75 | X33: 3.0293
C34: 46279 | D34: 722 | E34: 792.5 | F34: 7.3625 | G34: 533.25 | H34: 1320.25 | I34: 356.2 | J34: 70.19 | K34: 5052 | L34: 10038 | M34: 3384 | N34: 9024 | O34: 2349 | P34: 10192 | Q34: 555.5 | R34: 834.3 | S34: 2.07 | T34: 4.54 | U34: 1320.25 | V34: 92.6 | W34: 96.85 | X34: 2.9522
C35: 46276 | D35: 725.25 | E35: 798.5 | F35: 7.45 | G35: 530.25 | H35: 1312 | I35: 352.8 | J35: 69.68 | K35: 5056 | L35: 10151 | M35: 3422 | N35: 9103 | O35: 2369 | P35: 10226 | Q35: 553 | R35: 827.1 | S35: 2.065 | T35: 4.5584 | U35: 1320.5 | V35: 91.43 | W35: 95.69 | X35: 2.939
C36: 46275 | D36: 741.25 | E36: 818.75 | F36: 7.625 | G36: 533.75 | H36: 1347.25 | I36: 356.9 | J36: 71.92 | K36: 5154 | L36: 10177 | M36: 3399 | N36: 9054 | O36: 2358 | P36: 10248 | Q36: 559.25 | R36: 849.4 | S36: 2.06 | T36: 4.6271 | U36: 1323.25 | V36: 93.93 | W36: 98.36 | X36: 3.024
C37: 46274 | D37: 728.75 | E37: 806.25 | F37: 7.48 | G37: 527.75 | H37: 1325.25 | I37: 351.4 | J37: 70.57 | K37: 5220 | L37: 10306 | M37: 3397 | N37: 9122 | O37: 2376 | P37: 10392 | Q37: 559 | R37: 841.2 | S37: 2.03 | T37: 4.4346 | U37: 1257.75 | V37: 89.32 | W37: 93.6 | X37: 2.8969
C38: 46273 | D38: 747 | E38: 819 | F38: 7.54 | G38: 533.5 | H38: 1332 | I38: 349.8 | J38: 70.7 | K38: 5224 | L38: 10421 | M38: 3415 | N38: 9210 | O38: 2398 | P38: 10377 | Q38: 558.75 | R38: 848.3 | S38: 2.055 | T38: 4.2527 | U38: 1225 | V38: 87.14 | W38: 91.3 | X38: 2.8931
C39: 46272 | K39: 5214 | L39: 10264 | M39: 3404 | N39: 9142 | O39: 2400 | P39: 10238 | Q39: 556.5 | U39: 1237.25 | W39: 89.94
C40: 46269 | D40: 734 | E40: 802.25 | F40: 7.45 | G40: 536.75 | H40: 1325 | I40: 355.1 | J40: 69.27 | K40: 5155 | L40: 10212 | M40: 3402 | N40: 9144 | O40: 2397 | P40: 10152 | Q40: 553.5 | R40: 832.7 | S40: 2.08 | T40: 4.2091 | U40: 1200 | V40: 85.46 | W40: 89.15 | X40: 2.8345
...

Sheet VaR
A1: /WZ25 | B1: /KWZ25 | C1: /MWEZ25 | D1: /CZ25 | E1: /SF26 | F1: /SMZ25 | G1: /BOZ25 | H1: /FCPOF26 | I1: /DCPF6 | J1: /DSMF6 | K1: /DBYF6 | L1: /CRSMF6 | M1: /COIF6 | N1: /COMG6 | O1: /RSF6 | P1: /CUUZ25 | Q1: /HOZ25 | R1: /LGOZ5 | S1: /CLF26 | T1: /LCOJ6 | U1: /RBG26 | AD1: 60 | AE1: {=_xlfn._xlws.PY(0,1,VaR[#All])} -> #VALUE! | AF1: Create dataframe | AU1: ="n="&AD1 -> n=60 | AY1: % | BA1: Base Unit | BC1: $/MT | BH1: {=_xlfn._xlws.PY(1,1)} -> #VALUE!
A2: 660.5 | B2: 704 | C2: 6.765 | D2: 474.25 | E2: 1261.25 | F2: 357.1 | G2: 67.13 | H2: 4676 | I2: 9418 | J2: 3299 | K2: 8834 | L2: 2345 | M2: 10311 | N2: 552 | O2: 811.6 | P2: 2.1 | Q2: 4.7232 | R2: 1369.5 | S2: 99.02 | T2: 106.82 | U2: 3.1443 | AE2: {=_xlfn._xlws.PY(2,0,AD1)} | AF2: mean | AG2: stdev | AH2: p1 | AI2: p5 | AJ2: p95 | AK2: p99 | AM2: {=_xlfn._xlws.PY(3,0,AD1)} | AN2: mean | AO2: stdev | AP2: p1 | AQ2: p5 | AR2: p95 | AS2: p99 | AU2: Unit | AV2: Commodity | AW2: Mean | AX2: σ | AY2: Z_95 | AZ2: Z_99 | BA2: Z_95 | BB2: Z_99 | BC2: Z_95 | BD2: Z_99 | BF2: Conversion
A3: 670 | B3: 713 | C3: 6.86 | D3: 478 | E3: 1263 | F3: 359.8 | G3: 67.15 | H3: 4619 | I3: 9566 | J3: 3340 | K3: 8921 | L3: 2370 | M3: 10318 | N3: 554.75 | O3: 813.7 | P3: 2.095 | Q3: 4.6545 | R3: 1386.75 | S3: 96.5 | T3: 103.17 | U3: 3.0798 | AE3: /WZ25 | AF3: -1.2541667 | AG3: 12.746676 | AH3: -30.907368 | AI3: -22.220582 | AJ3: 19.712249 | AK3: 28.399035 | AM3: /WZ25 | AN3: -0.0016325426 | AO3: 0.018083156 | AP3: -0.043700255 | AQ3: -0.031376688 | AR3: 0.028111603 | AS3: 0.04043517 | AU3: c/bu | AV3: Wheat | AW3: =AN3 -> -0.0016325426 | AX3: =AO3 -> 0.018083156 | AY3: =AVERAGE(ABS(AQ3),AR3) -> 0.029744145 | AZ3: =AVERAGE(ABS(AP3),AS3) -> 0.042067712 | BA3: =AVERAGE(ABS(AI3),AJ3) -> 20.966415 | BB3: =AVERAGE(ABS(AH3),AK3) -> 29.653201 | BC3: =BA3*BF3 -> 7.703061 | BD3: =BB3*BF3 -> 10.894586 | BF3: 0.3674
A4: 673.25 | B4: 715 | C4: 6.9 | D4: 480.75 | E4: 1277.25 | F4: 364.5 | G4: 67.06 | H4: 4700 | I4: 9741 | J4: 3373 | K4: 9033 | L4: 2393 | M4: 10459 | N4: 559.25 | O4: 824.6 | P4: 2.075 | Q4: 4.7508 | R4: 1404 | S4: 93.9 | T4: 103.4 | U4: 3.142 | AE4: /KWZ25 | AF4: -1.5291667 | AG4: 12.664937 | AH4: -30.992215 | AI4: -22.361133 | AJ4: 19.3028 | AK4: 27.933882 | AM4: /KWZ25 | AN4: -0.0018955796 | AO4: 0.016569398 | AP4: -0.040441764 | AQ4: -0.029149815 | AR4: 0.025358655 | AS4: 0.036650605 | AU4: c/bu | AV4: Kansas Wheat | AW4: =AN4 -> -0.0018955796 | AX4: =AO4 -> 0.016569398 | AY4: =AVERAGE(ABS(AQ4),AR4) -> 0.027254235 | AZ4: =AVERAGE(ABS(AP4),AS4) -> 0.038546185 | BA4: =AVERAGE(ABS(AI4),AJ4) -> 20.831967 | BB4: =AVERAGE(ABS(AH4),AK4) -> 29.463048 | BC4: =BA4*BF4 -> 7.6536646 | BD4: =BB4*BF4 -> 10.824724 | BF4: 0.3674
A5: 669.25 | B5: 712.25 | C5: 6.94 | D5: 482.75 | E5: 1283.75 | F5: 363.2 | G5: 68.02 | H5: 4682 | I5: 9639 | J5: 3373 | K5: 8962 | L5: 2378 | M5: 10394 | N5: 559.25 | O5: 826.6 | P5: 2.09 | Q5: 4.7766 | R5: 1410.75 | S5: 93.17 | T5: 102.91 | U5: 3.1338 | AE5: /MWEZ25 | AF5: -0.014166667 | AG5: 0.10045729 | AH5: -0.24786526 | AI5: -0.1794042 | AJ5: 0.15107087 | AK5: 0.21953193 | AM5: /MWEZ25 | AN5: -0.0018797939 | AO5: 0.013756671 | AP5: -0.033882596 | AQ5: -0.024507504 | AR5: 0.020747916 | AS5: 0.030123008 | AU5: $/bu | AV5: Minneapolis Wheat | AW5: =AN5 -> -0.0018797939 | AX5: =AO5 -> 0.013756671 | AY5: =AVERAGE(ABS(AQ5),AR5) -> 0.02262771 | AZ5: =AVERAGE(ABS(AP5),AS5) -> 0.032002802 | BA5: =AVERAGE(ABS(AI5),AJ5) -> 0.16523753 | BB5: =AVERAGE(ABS(AH5),AK5) -> 0.2336986 | BC5: =BA5*BF5 -> 6.070827 | BD5: =BB5*BF5 -> 8.5860865 | BF5: 36.74
A6: 672.25 | B6: 715.25 | C6: 6.9625 | D6: 483 | E6: 1287.75 | F6: 368.7 | G6: 68.63 | H6: 4637 | I6: 9700 | J6: 3383 | K6: 9008 | L6: 2368 | M6: 10374 | N6: 552.25 | P6: 2.11 | Q6: 4.5868 | R6: 1371.25 | S6: 92.86 | T6: 103.2 | U6: 3.1706 | AE6: /CZ25 | AF6: -0.12083333 | AG6: 7.459423 | AH6: -17.474046 | AI6: -12.390492 | AJ6: 12.148826 | AK6: 17.232379 | AM6: /CZ25 | AN6: -0.00015340277 | AO6: 0.014975787 | AP6: -0.034992294 | AQ6: -0.024786381 | AR6: 0.024479576 | AS6: 0.034685489 | AU6: c/bu | AV6: Corn | AW6: =AN6 -> -0.00015340277 | AX6: =AO6 -> 0.014975787 | AY6: =AVERAGE(ABS(AQ6),AR6) -> 0.024632978 | AZ6: =AVERAGE(ABS(AP6),AS6) -> 0.034838891 | BA6: =AVERAGE(ABS(AI6),AJ6) -> 12.269659 | BB6: =AVERAGE(ABS(AH6),AK6) -> 17.353213 | BC6: =BA6*BF6 -> 4.8293377 | BD6: =BB6*BF6 -> 6.8302245 | BF6: 0.3936
A7: 671 | B7: 719.25 | C7: 6.9525 | D7: 479.75 | E7: 1292 | F7: 365.6 | G7: 68.02 | H7: 4592 | I7: 9662 | J7: 3389 | K7: 8995 | L7: 2365 | M7: 10301 | N7: 555.75 | O7: 829.8 | P7: 2.0675 | Q7: 4.5884 | R7: 1376 | S7: 91.01 | T7: 101.25 | U7: 3.1534 | AE7: /SF26 | AF7: 0.2625 | AG7: 14.236756 | AH7: -32.857147 | AI7: -23.15488 | AJ7: 23.67988 | AK7: 33.382147 | AM7: /SF26 | AN7: 0.0002763678 | AO7: 0.011235609 | AP7: -0.025861567 | AQ7: -0.018204564 | AR7: 0.0187573 | AS7: 0.026414303 | AU7: c/bu | AV7: Soy | AW7: =AN7 -> 0.0002763678 | AX7: =AO7 -> 0.011235609 | AY7: =AVERAGE(ABS(AQ7),AR7) -> 0.018480932 | AZ7: =AVERAGE(ABS(AP7),AS7) -> 0.026137935 | BA7: =AVERAGE(ABS(AI7),AJ7) -> 23.41738 | BB7: =AVERAGE(ABS(AH7),AK7) -> 33.119647 | BC7: =BA7*BF7 -> 8.6035453 | BD7: =BB7*BF7 -> 12.168158 | BF7: 0.3674
A8: 683.25 | B8: 736.25 | C8: 7.06 | D8: 500.25 | E8: 1287.5 | F8: 357.6 | G8: 67.92 | H8: 4661 | I8: 9564 | J8: 3388 | K8: 8933 | L8: 2352 | M8: 10277 | N8: 557.25 | O8: 828.9 | P8: 2.085 | Q8: 4.7165 | R8: 1391.25 | S8: 90.75 | T8: 100.96 | U8: 3.1596 | AE8: /SMZ25 | AF8: 0.49166667 | AG8: 5.1649829 | AH8: -11.52388 | AI8: -8.0039741 | AJ8: 8.9873075 | AK8: 12.507214 | AM8: /SMZ25 | AN8: 0.0015280748 | AO8: 0.014742805 | AP8: -0.032768817 | AQ8: -0.022721681 | AR8: 0.02577783 | AS8: 0.035824967 | AU8: $/st | AV8: SBM | AW8: =AN8 -> 0.0015280748 | AX8: =AO8 -> 0.014742805 | AY8: =AVERAGE(ABS(AQ8),AR8) -> 0.024249756 | AZ8: =AVERAGE(ABS(AP8),AS8) -> 0.034296892 | BA8: =AVERAGE(ABS(AI8),AJ8) -> 8.4956408 | BB8: =AVERAGE(ABS(AH8),AK8) -> 12.015547 | BC8: =BA8*BF8 -> 9.3647449 | BD8: =BB8*BF8 -> 13.244737 | BF8: 1.1023
A9: 686.5 | B9: 738.5 | C9: 7.1025 | D9: 502 | E9: 1297.5 | F9: 365.8 | G9: 67.68 | H9: 4524 | N9: 552.75 | O9: 822.9 | P9: 2.07 | Q9: 4.4766 | R9: 1333 | S9: 87.55 | T9: 97.45 | U9: 3.0711 | AE9: /BOZ25 | AF9: -0.11866667 | AG9: 1.0391644 | AH9: -2.5361245 | AI9: -1.82794 | AJ9: 1.5906066 | AK9: 2.2987912 | AM9: /BOZ25 | AN9: -0.0015858826 | AO9: 0.014886736 | AP9: -0.036217608 | AQ9: -0.026072384 | AR9: 0.022900618 | AS9: 0.033045843 | AU9: c/lb | AV9: SBO | AW9: =AN9 -> -0.0015858826 | AX9: =AO9 -> 0.014886736 | AY9: =AVERAGE(ABS(AQ9),AR9) -> 0.024486501 | AZ9: =AVERAGE(ABS(AP9),AS9) -> 0.034631726 | BA9: =AVERAGE(ABS(AI9),AJ9) -> 1.7092733 | BB9: =AVERAGE(ABS(AH9),AK9) -> 2.4174578 | BC9: =BA9*BF9 -> 37.672383 | BD9: =BB9*BF9 -> 53.280771 | BF9: 22.04
A10: 704.25 | B10: 756.25 | C10: 7.1975 | D10: 508 | E10: 1303 | F10: 354.8 | G10: 69.91 | H10: 4560 | N10: 561 | O10: 839 | P10: 2.08 | Q10: 4.4231 | R10: 1257 | S10: 88.43 | T10: 97.59 | U10: 3.088 | AE10: /FCPOF26 | AF10: 1.1333333 | AG10: 47.358162 | AH10: -109.03823 | AI10: -76.763911 | AJ10: 79.030577 | AK10: 111.30489 | AM10: /FCPOF26 | AN10: 0.00028148589 | AO10: 0.0099225393 | AP10: -0.022801792 | AQ10: -0.016039639 | AR10: 0.016602611 | AS10: 0.023364764 | AU10: myr/MT | AV10: CPO | AW10: =AN10 -> 0.00028148589 | AX10: =AO10 -> 0.0099225393 | AY10: =AVERAGE(ABS(AQ10),AR10) -> 0.016321125 | AZ10: =AVERAGE(ABS(AP10),AS10) -> 0.023083278 | BA10: =AVERAGE(ABS(AI10),AJ10) -> 77.897244 | BB10: =AVERAGE(ABS(AH10),AK10) -> 110.17156 | BC10: =BA10*BF10 -> 18.77042 | BD10: =BB10*BF10 -> 26.547364 | BF10: =1/4.15 -> 0.24096386 | BG10: myr
A11: 692.25 | B11: 742.25 | C11: 7.085 | D11: 497.25 | E11: 1280.75 | F11: 347.1 | G11: 69.35 | H11: 4578 | N11: 558 | O11: 832.8 | P11: 2.055 | Q11: 4.4001 | R11: 1301.5 | S11: 88.2 | T11: 97.58 | U11: 3.0719 | AE11: /DCPF6 | AF11: -0.33333333 | AG11: 79.884592 | AH11: -186.17268 | AI11: -131.73179 | AJ11: 131.06513 | AK11: 185.50602 | AM11: /DCPF6 | AN11: -8.0373658e-06 | AO11: 0.0080864081 | AP11: -0.018819836 | AQ11: -0.013308995 | AR11: 0.01329292 | AS11: 0.018803761 | AU11: cny/MT | AV11: DCE Palm | AW11: =AN11 -> -8.0373658e-06 | AX11: =AO11 -> 0.0080864081 | AY11: =AVERAGE(ABS(AQ11),AR11) -> 0.013300958 | AZ11: =AVERAGE(ABS(AP11),AS11) -> 0.018811798 | BA11: =AVERAGE(ABS(AI11),AJ11) -> 131.39846 | BB11: =AVERAGE(ABS(AH11),AK11) -> 185.83935 | BC11: =BA11*BF11 -> 18.45484 | BD11: =BB11*BF11 -> 26.101032 | BF11: =1/7.12 -> 0.14044944 | BG11: cny
A12: 683 | B12: 735.25 | C12: 6.98 | D12: 497.75 | E12: 1278.25 | F12: 347.5 | G12: 68.62 | H12: 4535 | N12: 555.25 | O12: 828.7 | P12: 2.1 | Q12: 4.3573 | R12: 1265.5 | S12: 89.43 | T12: 98.71 | U12: 3.1119 | AE12: /DSMF6 | AF12: 2.9833333 | AG12: 24.833337 | AH12: -54.787648 | AI12: -37.863871 | AJ12: 43.830538 | AK12: 60.754314 | AM12: /DSMF6 | AN12: 0.00095749763 | AO12: 0.0075171136 | AP12: -0.016529924 | AQ12: -0.011407054 | AR12: 0.013322049 | AS12: 0.018444919 | AU12: cny/MT | AV12: DCE Meal | AW12: =AN12 -> 0.00095749763 | AX12: =AO12 -> 0.0075171136 | AY12: =AVERAGE(ABS(AQ12),AR12) -> 0.012364552 | AZ12: =AVERAGE(ABS(AP12),AS12) -> 0.017487421 | BA12: =AVERAGE(ABS(AI12),AJ12) -> 40.847205 | BB12: =AVERAGE(ABS(AH12),AK12) -> 57.770981 | BC12: =BA12*BF12 -> 5.7369669 | BD12: =BB12*BF12 -> 8.1139018 | BF12: =1/7.12 -> 0.14044944
A13: 682.75 | B13: 737.5 | C13: 6.9675 | D13: 502.25 | E13: 1284 | F13: 353.3 | G13: 67.38 | H13: 4554 | N13: 551.75 | O13: 825.2 | P13: 2.115 | Q13: 4.4906 | R13: 1335.75 | S13: 90.84 | T13: 98.43 | U13: 3.1729 | AE13: /DBYF6 | AF13: 5.2 | AG13: 55.701931 | AH13: -124.38207 | AI13: -86.421523 | AJ13: 96.821523 | AK13: 134.78207 | AM13: /DBYF6 | AN13: 0.00061414362 | AO13: 0.0062962084 | AP13: -0.014033027 | AQ13: -0.0097421976 | AR13: 0.010970485 | AS13: 0.015261315 | AU13: cny/MT | AV13: DCE BO | AW13: =AN13 -> 0.00061414362 | AX13: =AO13 -> 0.0062962084 | AY13: =AVERAGE(ABS(AQ13),AR13) -> 0.010356341 | AZ13: =AVERAGE(ABS(AP13),AS13) -> 0.014647171 | BA13: =AVERAGE(ABS(AI13),AJ13) -> 91.621523 | BB13: =AVERAGE(ABS(AH13),AK13) -> 129.58207 | BC13: =BA13*BF13 -> 12.868191 | BD13: =BB13*BF13 -> 18.199729 | BF13: =1/7.12 -> 0.14044944
A14: 675.75 | B14: 733 | C14: 6.9325 | D14: 500.75 | E14: 1293 | F14: 356.9 | G14: 68.28 | H14: 4610 | I14: 9593 | J14: 3369 | K14: 8934 | L14: 2332 | M14: 10217 | N14: 554 | P14: 2.14 | Q14: 4.5068 | R14: 1350.25 | S14: 88.42 | T14: 95.09 | U14: 3.0472 | AE14: /CRSMF6 | AF14: 1.4333333 | AG14: 21.440787 | AH14: -48.445396 | AI14: -33.833623 | AJ14: 36.700289 | AK14: 51.312062 | AM14: /CRSMF6 | AN14: 0.00066726029 | AO14: 0.0091988433 | AP14: -0.020732449 | AQ14: -0.01446349 | AR14: 0.015798011 | AS14: 0.02206697 | AU14: cny/MT | AV14: ZZ RSM | AW14: =AN14 -> 0.00066726029 | AX14: =AO14 -> 0.0091988433 | AY14: =AVERAGE(ABS(AQ14),AR14) -> 0.015130751 | AZ14: =AVERAGE(ABS(AP14),AS14) -> 0.02139971 | BA14: =AVERAGE(ABS(AI14),AJ14) -> 35.266956 | BB14: =AVERAGE(ABS(AH14),AK14) -> 49.878729 | BC14: =BA14*BF14 -> 4.9532242 | BD14: =BB14*BF14 -> 7.0054395 | BF14: =1/7.12 -> 0.14044944
A15: 692.75 | B15: 743 | C15: 6.9925 | D15: 522 | E15: 1297.75 | F15: 359 | G15: 68.36 | H15: 4624 | I15: 9571 | J15: 3347 | K15: 8855 | L15: 2298 | M15: 10044 | N15: 557.75 | O15: 837.1 | P15: 2.145 | Q15: 4.3323 | R15: 1297.25 | S15: 87.25 | T15: 93.51 | U15: 2.9459 | AE15: /COIF6 | AF15: 8.9333333 | AG15: 78.140869 | AH15: -172.84951 | AI15: -119.59696 | AJ15: 137.46363 | AK15: 190.71618 | AM15: /COIF6 | AN15: 0.00091709066 | AO15: 0.0076943752 | AP15: -0.016982703 | AQ15: -0.01173903 | AR15: 0.013573212 | AS15: 0.018816884 | AU15: cny/MT | AV15: ZZ RSO | AW15: =AN15 -> 0.00091709066 | AX15: =AO15 -> 0.0076943752 | AY15: =AVERAGE(ABS(AQ15),AR15) -> 0.012656121 | AZ15: =AVERAGE(ABS(AP15),AS15) -> 0.017899793 | BA15: =AVERAGE(ABS(AI15),AJ15) -> 128.53029 | BB15: =AVERAGE(ABS(AH15),AK15) -> 181.78285 | BC15: =BA15*BF15 -> 18.052007 | BD15: =BB15*BF15 -> 25.531299 | BF15: =1/7.12 -> 0.14044944
A16: 688.75 | B16: 745.75 | C16: 7.0175 | D16: 523 | E16: 1288.25 | F16: 359.4 | G16: 67.66 | H16: 4664 | I16: 9675 | J16: 3386 | K16: 8883 | L16: 2337 | M16: 10134 | N16: 548.25 | O16: 821.8 | P16: 2.185 | Q16: 4.3681 | R16: 1336.75 | S16: 89.01 | T16: 94.4 | U16: 2.968 | AE16: /COMG6 | AF16: 0.033333333 | AG16: 5.878081 | AH16: -13.641128 | AI16: -9.6352495 | AJ16: 9.7019162 | AK16: 13.707795 | AM16: /COMG6 | AN16: 0.00011870527 | AO16: 0.010862368 | AP16: -0.025150941 | AQ16: -0.0177483 | AR16: 0.017985711 | AS16: 0.025388352 | AU16: eur/MT | AV16: Matif RS | AW16: =AN16 -> 0.00011870527 | AX16: =AO16 -> 0.010862368 | AY16: =AVERAGE(ABS(AQ16),AR16) -> 0.017867005 | AZ16: =AVERAGE(ABS(AP16),AS16) -> 0.025269647 | BA16: =AVERAGE(ABS(AI16),AJ16) -> 9.6685828 | BB16: =AVERAGE(ABS(AH16),AK16) -> 13.674461 | BC16: =BA16*BF16 -> 11.176882 | BD16: =BB16*BF16 -> 15.807677 | BF16: 1.156
A17: 703.25 | B17: 762 | C17: 7.135 | D17: 528.25 | E17: 1319 | F17: 371 | G17: 67.84 | H17: 4672 | N17: 557.5 | O17: 841.4 | P17: 2.21 | Q17: 4.3746 | R17: 1346.25 | S17: 88.71 | T17: 94.11 | U17: 2.9827 | AE17: /RSF6 | AF17: 0.40333333 | AG17: 13.310846 | AH17: -30.562326 | AI17: -21.491061 | AJ17: 22.297727 | AK17: 31.368993 | AM17: /RSF6 | AN17: 0.00063757119 | AO17: 0.016239283 | AP17: -0.037140649 | AQ17: -0.026073672 | AR17: 0.027348814 | AS17: 0.038415792 | AU17: cad/MT | AV17: ICE RS | AW17: =AN17 -> 0.00063757119 | AX17: =AO17 -> 0.016239283 | AY17: =AVERAGE(ABS(AQ17),AR17) -> 0.026711243 | AZ17: =AVERAGE(ABS(AP17),AS17) -> 0.03777822 | BA17: =AVERAGE(ABS(AI17),AJ17) -> 21.894394 | BB17: =AVERAGE(ABS(AH17),AK17) -> 30.965659 | BC17: =BA17*BF17 -> 15.624345 | BD17: =BB17*BF17 -> 22.097809 | BF17: =1/1.4013 -> 0.71362306
A18: 707 | B18: 767 | C18: 7.2025 | D18: 527.5 | E18: 1317.5 | F18: 372.4 | G18: 67.55 | H18: 4772 | I18: 9787 | J18: 3405 | K18: 8943 | L18: 2347 | M18: 10236 | N18: 557.75 | O18: 841.2 | P18: 2.18 | Q18: 4.4197 | R18: 1385.5 | S18: 90.9 | T18: 96.42 | U18: 3.095 | AE18: /CUUZ25 | AF18: 0.0035416667 | AG18: 0.023162523 | AH18: -0.050342419 | AI18: -0.034557293 | AJ18: 0.041640627 | AK18: 0.057425753 | AM18: /CUUZ25 | AN18: 0.0018240936 | AO18: 0.011249487 | AP18: -0.024346126 | AQ18: -0.016679666 | AR18: 0.020327853 | AS18: 0.027994313 | AU18: $/gal | AV18: Ethanol | AW18: =AN18 -> 0.0018240936 | AX18: =AO18 -> 0.011249487 | AY18: =AVERAGE(ABS(AQ18),AR18) -> 0.018503759 | AZ18: =AVERAGE(ABS(AP18),AS18) -> 0.02617022 | BA18: =AVERAGE(ABS(AI18),AJ18) -> 0.03809896 | BB18: =AVERAGE(ABS(AH18),AK18) -> 0.053884086 | BC18: =BA18*BF18 -> 12.755532 | BD18: =BB18*BF18 -> 18.040392 | BF18: 334.8
A19: 708.5 | B19: 771.75 | C19: 7.2875 | D19: 529 | E19: 1318 | F19: 370.6 | G19: 67.81 | H19: 4768 | I19: 9740 | J19: 3414 | K19: 8927 | L19: 2361 | M19: 10145 | N19: 561.75 | O19: 837.2 | P19: 2.175 | Q19: 4.5171 | R19: 1344 | S19: 89.51 | T19: 95.03 | U19: 3.0751 | AE19: /HOZ25 | AF19: 0.017825 | AG19: 0.099775564 | AH19: -0.21428767 | AI19: -0.1462912 | AJ19: 0.1819412 | AK19: 0.24993767 | AM19: /HOZ25 | AN19: 0.0046007422 | AO19: 0.024186073 | AP19: -0.051664477 | AQ19: -0.035181808 | AR19: 0.044383292 | AS19: 0.060865962 | AU19: $/gal | AV19: Heating Oil | AW19: =AN19 -> 0.0046007422 | AX19: =AO19 -> 0.024186073 | AY19: =AVERAGE(ABS(AQ19),AR19) -> 0.03978255 | AZ19: =AVERAGE(ABS(AP19),AS19) -> 0.05626522 | BA19: =AVERAGE(ABS(AI19),AJ19) -> 0.1641162 | BB19: =AVERAGE(ABS(AH19),AK19) -> 0.23211267 | BC19: =BA19*BF19 -> 51.023726 | BD19: =BB19*BF19 -> 72.16383 | BF19: 310.9
A20: 717.25 | B20: 781.25 | C20: 7.3625 | D20: 536.75 | E20: 1325.5 | F20: 370.7 | G20: 67.92 | H20: 4810 | I20: 9859 | J20: 3410 | K20: 8946 | L20: 2362 | M20: 10243 | N20: 560 | O20: 836.1 | P20: 2.185 | Q20: 4.5489 | R20: 1311 | S20: 87.98 | T20: 92.74 | U20: 2.9699 | AE20: /LGOZ5 | AF20: 6.1 | AG20: 32.396157 | AH20: -69.264732 | AI20: -47.186937 | AJ20: 59.386937 | AK20: 81.464732 | AM20: /LGOZ5 | AN20: 0.0055420811 | AO20: 0.02663124 | AP20: -0.056411447 | AQ20: -0.03826241 | AR20: 0.049346573 | AS20: 0.06749561 | AU20: $/MT | AV20: ICE GO | AW20: =AN20 -> 0.0055420811 | AX20: =AO20 -> 0.02663124 | AY20: =AVERAGE(ABS(AQ20),AR20) -> 0.043804492 | AZ20: =AVERAGE(ABS(AP20),AS20) -> 0.061953528 | BA20: =AVERAGE(ABS(AI20),AJ20) -> 53.286937 | BB20: =AVERAGE(ABS(AH20),AK20) -> 75.364732 | BC20: =BA20*BF20 -> 53.286937 | BD20: =BB20*BF20 -> 75.364732 | BF20: 1
A21: 726.75 | B21: 794.5 | C21: 7.4625 | D21: 543 | E21: 1328 | F21: 368.4 | G21: 68.85 | H21: 4857 | I21: 9876 | J21: 3391 | K21: 8897 | L21: 2347 | M21: 10186 | N21: 563.25 | O21: 846.8 | P21: 2.19 | Q21: 4.4851 | R21: 1305.75 | S21: 89.16 | T21: 93.4 | U21: 2.9445 | AE21: /CLF26 | AF21: 0.31166667 | AG21: 1.8494857 | AH21: -3.9908803 | AI21: -2.7304665 | AJ21: 3.3537998 | AK21: 4.6142137 | AM21: /CLF26 | AN21: 0.003761533 | AO21: 0.022116392 | AP21: -0.047688889 | AQ21: -0.032616695 | AR21: 0.040139761 | AS21: 0.055211955 | AU21: $/bl | AV21: Light Crude | AW21: =AN21 -> 0.003761533 | AX21: =AO21 -> 0.022116392 | AY21: =AVERAGE(ABS(AQ21),AR21) -> 0.036378228 | AZ21: =AVERAGE(ABS(AP21),AS21) -> 0.051450422 | BA21: =AVERAGE(ABS(AI21),AJ21) -> 3.0421332 | BB21: =AVERAGE(ABS(AH21),AK21) -> 4.302547 | BC21: =BA21*BF21 -> 22.755156 | BD21: =BB21*BF21 -> 32.183052 | BF21: 7.48
A22: 714.25 | B22: 783.75 | C22: 7.4125 | D22: 527.5 | E22: 1303.5 | F22: 358.6 | G22: 68.22 | H22: 4898 | I22: 9907 | J22: 3429 | K22: 8905 | L22: 2389 | M22: 10113 | N22: 557.25 | O22: 833 | P22: 2.16 | Q22: 4.5875 | R22: 1351.75 | S22: 92.05 | T22: 96.03 | U22: 3.0015 | AE22: /LCOJ6 | AF22: 0.38466667 | AG22: 1.8741013 | AH22: -3.975145 | AI22: -2.6979557 | AJ22: 3.467289 | AK22: 4.7444783 | AM22: /LCOJ6 | AN22: 0.004287495 | AO22: 0.021319156 | AP22: -0.045308279 | AQ22: -0.030779396 | AR22: 0.039354386 | AS22: 0.053883269 | AU22: $/bl | AV22: Brent Crude | AW22: =AN22 -> 0.004287495 | AX22: =AO22 -> 0.021319156 | AY22: =AVERAGE(ABS(AQ22),AR22) -> 0.035066891 | AZ22: =AVERAGE(ABS(AP22),AS22) -> 0.049595774 | BA22: =AVERAGE(ABS(AI22),AJ22) -> 3.0826224 | BB22: =AVERAGE(ABS(AH22),AK22) -> 4.3598117 | BC22: =BA22*BF22 -> 23.058015 | BD22: =BB22*BF22 -> 32.611391 | BF22: 7.48
A23: 727 | B23: 794.5 | C23: 7.525 | D23: 530.5 | E23: 1319.75 | F23: 371.3 | G23: 69.15 | H23: 4936 | I23: 10070 | J23: 3480 | K23: 9017 | L23: 2421 | M23: 10211 | N23: 556 | O23: 844.1 | P23: 2.135 | Q23: 4.6262 | R23: 1338.25 | S23: 92.61 | T23: 96.15 | U23: 2.9994 | AE23: /RBG26 | AF23: 0.0075733333 | AG23: 0.057207413 | AH23: -0.12551101 | AI23: -0.086524487 | AJ23: 0.10167115 | AK23: 0.14065768 | AM23: /RBG26 | AN23: 0.0028360479 | AO23: 0.020465027 | AP23: -0.044772725 | AQ23: -0.030825927 | AR23: 0.036498022 | AS23: 0.050444821 | AU23: $/bl | AV23: RBOB | AW23: =AN23 -> 0.0028360479 | AX23: =AO23 -> 0.020465027 | AY23: =AVERAGE(ABS(AQ23),AR23) -> 0.033661974 | AZ23: =AVERAGE(ABS(AP23),AS23) -> 0.047608773 | BA23: =AVERAGE(ABS(AI23),AJ23) -> 0.094097821 | BB23: =AVERAGE(ABS(AH23),AK23) -> 0.13308434 | BC23: =BA23*BF23 -> 32.934237 | BD23: =BB23*BF23 -> 46.57952 | BF23: 350
A24: 730.75 | B24: 799.5 | C24: 7.56 | D24: 534.25 | E24: 1320.5 | F24: 365.6 | G24: 69.67 | I24: 10066 | J24: 3434 | K24: 9000 | L24: 2372 | M24: 10169 | N24: 556.75 | O24: 837.8 | P24: 2.105 | Q24: 4.7155 | R24: 1364 | S24: 92.79 | T24: 96.69 | U24: 2.9871
A25: 728.5 | B25: 796.25 | C25: 7.485 | D25: 535.75 | E25: 1318.75 | F25: 365.4 | G25: 70.35 | H25: 4998 | I25: 10031 | J25: 3374 | K25: 8960 | L25: 2330 | M25: 10101 | N25: 558.5 | O25: 840.9 | P25: 2.105 | Q25: 4.7352 | R25: 1391.75 | S25: 95.51 | T25: 98.75 | U25: 3.0293
A26: 722 | B26: 792.5 | C26: 7.3625 | D26: 533.25 | E26: 1304.25 | F26: 356.2 | G26: 70.19 | H26: 4958 | I26: 10038 | J26: 3384 | K26: 9024 | L26: 2349 | M26: 10192 | N26: 555.5 | O26: 834.3 | P26: 2.07 | Q26: 4.54 | R26: 1320.25 | S26: 92.6 | T26: 96.85 | U26: 2.9522
